Workbook

Sheet Hoja1
A2: Cantón | C2: Region
A3: Delegación
A5: Participacion
A6: DISTRITO | G6: ¿Cuál es la relación con la zona?
A7: Distrito | B7: Porcentaje | C7: Total | D7: Comercio | E7: Comunidad | G7: Relación | H7: Porcentaje | I7: Comunidad
B8: =(C8/$C$24)*1 -> #DIV/0! | C8: =SUM(D8:E8) -> 0 | G8: Estudio en la zona | H8: =(I8/$I$12)*1 -> #DIV/0!
B9: =(C9/$C$24)*1 -> #DIV/0! | C9: =SUM(D9:E9) -> 0 | G9: Trabajo en la zona | H9: =(I9/$I$12)*1 -> #DIV/0!
B10: =(C10/$C$24)*1 -> #DIV/0! | C10: =SUM(D10:E10) -> 0 | G10: Visito la zona | H10: =(I10/$I$12)*1 -> #DIV/0!
B11: =(C11/$C$24)*1 -> #DIV/0! | C11: =SUM(D11:E11) -> 0 | G11: Vivo en la zona | H11: =(I11/$I$12)*1 -> #DIV/0!
B12: =(C12/$C$24)*1 -> #DIV/0! | C12: =SUM(D12:E12) -> 0 | H12: =SUM(H8:H11) -> #DIV/0! | I12: =SUM(I8:I11) -> 0
B13: =(C13/$C$24)*1 -> #DIV/0! | C13: =SUM(D13:E13) -> 0
B14: =(C14/$C$24)*1 -> #DIV/0! | C14: =SUM(D14:E14) -> 0
B15: =(C15/$C$24)*1 -> #DIV/0! | C15: =SUM(D15:E15) -> 0
B16: =(C16/$C$24)*1 -> #DIV/0! | C16: =SUM(D16:E16) -> 0
B17: =(C17/$C$24)*1 -> #DIV/0! | C17: =SUM(D17:E17) -> 0
B18: =(C18/$C$24)*1 -> #DIV/0! | C18: =SUM(D18:E18) -> 0
B19: =(C19/$C$24)*1 -> #DIV/0! | C19: =SUM(D19:E19) -> 0
B20: =(C20/$C$24)*1 -> #DIV/0! | C20: =SUM(D20:E20) -> 0
B21: =(C21/$C$24)*1 -> #DIV/0! | C21: =SUM(D21:E21) -> 0
B22: =(C22/$C$24)*1 -> #DIV/0! | C22: =SUM(D22:E22) -> 0
B23: =(C23/$C$24)*1 -> #DIV/0! | C23: =SUM(D23:E23) -> 0
A24: Total | B24: =SUM(B8:B23) -> #DIV/0! | C24: =SUM(C8:C23) -> 0 | D24: =SUM(D8:D23) -> 0 | E24: =SUM(E8:E23) -> 0
A27: Participación por edad
D28: Comunidad | E28: Comercio | F28: FP
A29: De 18 a 29 | B29: =(C29/$C$34)*1 -> #DIV/0! | C29: =SUM(D29:F29) -> 0
A30: De 30 a 44 | B30: =(C30/$C$34)*1 -> #DIV/0! | C30: =SUM(D30:F30) -> 0
A31: De 45 a 64 | B31: =(C31/$C$34)*1 -> #DIV/0! | C31: =SUM(D31:F31) -> 0
A32: De 65 años o más | B32: =(C32/$C$34)*1 -> #DIV/0! | C32: =SUM(D32:F32) -> 0
A33: Vacio | B33: =(C33/$C$34)*1 -> #DIV/0! | C33: =SUM(D33:F33) -> 0
B34: =SUM(B29:B33) -> #DIV/0! | C34: =SUM(C29:C33) -> 0 | D34: =SUM(D29:D33) -> 0 | E34: =SUM(E29:E33) -> 0 | F34: =SUM(F29:F33) -> 0
A37: Escolaridad
D38: Comunidad | E38: Comercio | F38: FP
A39: Ninguna | B39: =(C39/$C$47)*1 -> #DIV/0! | C39: =SUM(D39:F39) -> 0
A40: Primaria | B40: =(C40/$C$47)*1 -> #DIV/0! | C40: =SUM(D40:F40) -> 0
A41: Primaria incompleta | B41: =(C41/$C$47)*1 -> #DIV/0! | C41: =SUM(D41:F41) -> 0
A42: Secundaria completa | B42: =(C42/$C$47)*1 -> #DIV/0! | C42: =SUM(D42:F42) -> 0
A43: Secundaria incompleta | B43: =(C43/$C$47)*1 -> #DIV/0! | C43: =SUM(D43:F43) -> 0
A44: Técnico | B44: =(C44/$C$47)*1 -> #DIV/0! | C44: =SUM(D44:F44) -> 0
A45: Universidad | B45: =(C45/$C$47)*1 -> #DIV/0! | C45: =SUM(D45:F45) -> 0
A46: Universidad incompleta | B46: =(C46/$C$47)*1 -> #DIV/0! | C46: =SUM(D46:F46) -> 0
...

Sheet pareto
A1: categoria | B1: descriptor | C1: Frecuencia | D1: porcentaje | E1: Acumulado | F1: acumulado | G1: segmento

Sheet Hoja2
A2: Delitos | B2: Delitos
A3: ABANDONO DE PERSONAS (MENOR DE EDAD, ADULTO MAYOR O CON CAPACIDADES DIFERENTES) | B3: ABANDONO DE PERSONAS (MENOR DE EDAD, ADULTO MAYOR O CON CAPACIDADES DIFERENTES)
A4: ABIGEATO (ROBO Y DESTACE DE GANADO) | B4: ABIGEATO (ROBO Y DESTACE DE GANADO)
A5: ABORTO | B5: ABORTO
A6: ABUSO DE AUTORIDAD | B6: ABUSO DE AUTORIDAD
A7: ACCIONAMIENTO DE ARMA DE FUEGO (BALACERAS) | B7: ACCIONAMIENTO DE ARMA DE FUEGO (BALACERAS)
A8: ADMINISTRACION FRAUDULENTA, APROPIACIONES INDEBIDAS O ENRIQUECIMIENTO ILICITO | B8: ADMINISTRACION FRAUDULENTA, APROPIACIONES INDEBIDAS O ENRIQUECIMIENTO ILICITO
A9: AGRESION CON ARMAS | B9: AGRESION CON ARMAS
A10: ALTERACION DE DATOS Y SABOTAJE INFORMATICO | B10: ALTERACION DE DATOS Y SABOTAJE INFORMATICO
A11: AMENAZAS | B11: AMENAZAS
A12: CALUMNIA | B12: CALUMNIA
A13: CAZA ILEGAL | B13: CAZA ILEGAL
... A256: Pococí Norte | B256: D98
