Workbook

Sheet R1
A1: Delegacion Policial | X1: =AVERAGE(C3:C27) -> 1.1832914 | Y1: =1-X1 -> -0.18329143
A3: D1- Carmen | C3: ='D1 Carmen'!X1 -> 1.025662
A4: D2-Merced | C4: ='D2 Merced'!X1 -> 1.0575565
A5: D3-Hospital | C5: ='D3 Hospital'!X1 -> 1.0588932
A6: D4-Catedral | C6: ='D4 Catedral'!X1 -> 1.0041416
A7: D5-San Sebastián | C7: ='D5 San Sebastian'!X1 -> 1.0946083
A8: D6-Hatillo | C8: ='D6 Hatillo'!$X$1 -> 1.1045983
A9: D7-San Francisco y Zapote | C9: ='D7 Zapote'!$X$1 -> 1.2291228
A10: D8-Pavas | C10: ='D8 Pavas'!$X$1 -> 1.1290767
A11: D9-Mata Redonda y Uruca | C11: ='D9 Uruca'!$X$1 -> 1.1578709
A12: D10-Curridabat | C12: ='D10 Curridabat'!$X$1 -> 1.7030713
A13: D11-Montes de Oca | C13: ='D11 Montes de Oca'!$X$1 -> 1.0347848
A14: D12-Goicoechea | C14: ='D12 Goicochea'!$X$1 -> 1.50239
A15: D13-Moravia | C15: ='D13 Moravia'!$X$1 -> 1.3362505
A16: D14-Tibas | C16: ='D14 Tibas'!$X$1 -> 1.2473862
A17: D15-Coronado | C17: ='D15 Coronado'!$X$1 -> 1.0797179
A18: D16-Desmparados Norte | C18: ='D16 Desamparados N'!X1 -> 1.0754453
A19: D17- Desamparados Sur | C19: ='D17 Desamparados S'!X1 -> 1.1465287
A20: D18-Aserrí | C20: ='D18 Aserri'!X1 -> 1.6544534
A21: D19-Acosta | C21: ='D19 Acosta'!X1 -> 1.0303037
A22: D20-Alajuelita | C22: ='D20 Alajuelita'!X1 -> 1.3657517
A23: D21 Escazú | C23: ='D21 Escazu'!X1 -> 1.0262021
A24: D22-Santa Ana | C24: ='D22 Santa Ana'!X1 -> 1.0884836
A25: D23-Mora | C25: ='D23 Mora'!X1 -> 1.1343143
A26: D24-Puriscal | C26: ='D24 Puriscal'!X1 -> 1.2369023
A27: D25-Turrubares | C27: ='D25 Turrubares'!X1 -> 1.0587695

Sheet D1 Carmen
H1: Carmen | X1: =AVERAGE(L7,L11,L15) -> 1.025662 | Y1: =1-X1 -> -0.025661979
H4: Tipo | I4: Distrito | J4: Meta | K4: Contabilidad | L4: % Avance | M4: Pendiente
H5: Comunidad
I7: Carmen | J7: 338 | K7: 355 | L7: =K7/J7 -> 1.0502959 | M7: =J7-K7 -> -17
H9: Comercio
I11: Carmen | J11: 201 | K11: 204 | L11: =K11/J11 -> 1.0149254 | M11: =J11-K11 -> -3
H13: Policial
I15: Carmen | J15: 85 | K15: 86 | L15: =K15/J15 -> 1.0117647 | M15: =J15-K15 -> -1
I18: =TODAY() -> 46256

Sheet D2 Merced
H1: Merced | X1: =AVERAGE(L7,L11,L15) -> 1.0575565 | Y1: =1-X1 -> -0.057556526
H4: Tipo | I4: Distrito | J4: Meta | K4: Contabilidad | L4: % Avance | M4: Pendiente
H5: Comunidad
I7: Merced | J7: 375 | K7: 407 | L7: =K7/J7 -> 1.0853333 | M7: =J7-K7 -> -32
H9: Comercio
I11: Merced | J11: 229 | K11: 249 | L11: =K11/J11 -> 1.0873362 | M11: =J11-K11 -> -20
H13: Policial
I15: Merced | J15: 90 | K15: 90 | L15: =K15/J15 -> 1 | M15: =J15-K15 -> 0
I18: =TODAY() -> 46256

Sheet D3 Hospital
H1: Hospital | X1: =AVERAGE(L7,L11,L15) -> 1.0588932 | Y1: =1-X1 -> -0.058893152
H4: Tipo | I4: Distrito | J4: Meta | K4: Contabilidad | L4: % Avance | M4: Pendiente
H5: Comunidad
I7: Hospital | J7: 379 | K7: 429 | L7: =K7/J7 -> 1.1319261 | M7: =J7-K7 -> -50
H9: Comercio
I11: Hospital | J11: 254 | K11: 255 | L11: =K11/J11 -> 1.003937 | M11: =J11-K11 -> -1
H13: Policial
I15: Hospital | J15: 98 | K15: 102 | L15: =K15/J15 -> 1.0408163 | M15: =J15-K15 -> -4
I18: =TODAY() -> 46256

Sheet D4 Catedral
H1: Catedral | X1: =AVERAGE(L7,L11,L15) -> 1.0041416 | Y1: =1-X1 -> -0.0041415929
H4: Tipo | I4: Distrito | J4: Meta | K4: Contabilidad | L4: % Avance | M4: Pendiente
H5: Comunidad
I7: Catedral | J7: 375 | K7: 378 | L7: =K7/J7 -> 1.008 | M7: =J7-K7 -> -3
H9: Comercio
I11: Catedral | J11: 226 | K11: 227 | L11: =K11/J11 -> 1.0044248 | M11: =J11-K11 -> -1
H13: Policial
I15: Catedral | J15: 79 | K15: 79 | L15: =K15/J15 -> 1 | M15: =J15-K15 -> 0
I18: =TODAY() -> 46256

Sheet D5 San Sebastian
H1: San Sebastian | X1: =AVERAGE(L7,L11,L15) -> 1.0946083 | Y1: =1-X1 -> -0.094608272
H4: Tipo | I4: Distrito | J4: Meta | K4: Contabilidad | L4: % Avance | M4: Pendiente
H5: Comunidad
I7: San Sebastian | J7: 381 | K7: 397 | L7: =K7/J7 -> 1.0419948 | M7: =J7-K7 -> -16
H9: Comercio
I11: San Sebastian | J11: 153 | K11: 190 | L11: =K11/J11 -> 1.2418301 | M11: =J11-K11 -> -37
H13: Policial
I15: San Sebastian | J15: 47 | K15: 47 | L15: =K15/J15 -> 1 | M15: =J15-K15 -> 0
I18: =TODAY() -> 46256

Sheet D6 Hatillo
H1: Hatillo | X1: =AVERAGE(L7,L11,L15) -> 1.1045983 | Y1: =1-X1 -> -0.10459826
H4: Tipo | I4: Distrito | J4: Meta | K4: Contabilidad | L4: % Avance | M4: Pendiente
H5: Comunidad
I7: Hatillo | J7: 382 | K7: 392 | L7: =K7/J7 -> 1.026178 | M7: =J7-K7 -> -10
H9: Comercio
I11: Hatillo | J11: 117 | K11: 118 | L11: =K11/J11 -> 1.008547 | M11: =J11-K11 -> -1
H13: Policial
I15: Hatillo | J15: 43 | K15: 55 | L15: =K15/J15 -> 1.2790698 | M15: =J15-K15 -> -12
I18: =TODAY() -> 46256

Sheet D7 Zapote
H1: Zapote | X1: =AVERAGE(L7,L9,L13,L17) -> 1.2291228 | Y1: =1-X1 -> -0.22912285
H4: Tipo | I4: Distrito | J4: Meta | K4: Contabilidad | L4: % Avance | M4: Pendiente
H5: Comunidad
I7: Zapote | J7: 185 | K7: 293 | L7: =K7/J7 -> 1.5837838 | M7: =J7-K7 -> -108
I9: San Francisco | J9: 198 | K9: 263 | L9: =K9/J9 -> 1.3282828 | M9: =J9-K9 -> -65
H11: Comercio
I13: Zapote/San Francisco | J13: 226 | K13: 227 | L13: =K13/J13 -> 1.0044248 | M13: =J13-K13 -> -1
H15: Policial
I17: Zapote/San Francisco | J17: 43 | K17: 43 | L17: =K17/J17 -> 1 | M17: =J17-K17 -> 0
I20: =TODAY() -> 46256

Sheet D8 Pavas
H1: Pavas | X1: =AVERAGE(L7,L11,L15) -> 1.1290767 | Y1: =1-X1 -> -0.12907667
H4: Tipo | I4: Distrito | J4: Meta | K4: Contabilidad | L4: % Avance | M4: Pendiente
H5: Comunidad
I7: Pavas | J7: 383 | K7: 399 | L7: =K7/J7 -> 1.0417755 | M7: =J7-K7 -> -16
H9: Comercio
I11: Pavas | J11: 244 | K11: 244 | L11: =K11/J11 -> 1 | M11: =J11-K11 -> 0
H13: Policial
I15: Pavas | J15: 55 | K15: 74 | L15: =K15/J15 -> 1.3454545 | M15: =J15-K15 -> -19
I18: =TODAY() -> 46256

Sheet D9 Uruca
H1: Uruca | X1: =AVERAGE(L7,L9,L13,L17) -> 1.1578709 | Y1: =1-X1 -> -0.15787089
H4: Tipo | I4: Distrito | J4: Meta | K4: Contabilidad | L4: % Avance | M4: Pendiente
H5: Comunidad
I7: Uruca | J7: 311 | K7: 314 | L7: =K7/J7 -> 1.0096463 | M7: =J7-K7 -> -3
I9: Mata redonda | J9: 71 | K9: 108 | L9: =K9/J9 -> 1.5211268 | M9: =J9-K9 -> -37
H11: Comercio
I13: Uruca | J13: 272 | K13: 278 | L13: =K13/J13 -> 1.0220588 | M13: =J13-K13 -> -6
H15: Policial
I17: Uruca | J17: 89 | K17: 96 | L17: =K17/J17 -> 1.0786517 | M17: =J17-K17 -> -7
I20: =TODAY() -> 46256

Sheet D10 Curridabat
H1: Curridabat | X1: =AVERAGE(L7,L9,L11,L13,L17,L21) -> 1.7030713 | Y1: =1-X1 -> -0.70307134
H4: Tipo | I4: Distrito | J4: Meta | K4: Contabilidad | L4: % Avance | M4: Pendiente
H5: Comunidad
I7: Curridabat | J7: 147 | K7: 409 | L7: =K7/J7 -> 2.7823129 | M7: =J7-K7 -> -262
I9: Granadilla | J9: 93 | K9: 140 | L9: =K9/J9 -> 1.5053763 | M9: =J9-K9 -> -47
I11: Sanchez | J11: 33 | K11: 96 | L11: =K11/J11 -> 2.9090909 | M11: =J11-K11 -> -63
I13: Tirrases | J13: 109 | K13: 121 | L13: =K13/J13 -> 1.1100917 | M13: =J13-K13 -> -12
H15: Comercio
I17: Curridabat | J17: 235 | K17: 205 | L17: =K17/J17 -> 0.87234043 | M17: =J17-K17 -> 30
H19: Policial
I21: Curridabat | J21: 102 | K21: 106 | L21: =K21/J21 -> 1.0392157 | M21: =J21-K21 -> -4
I24: =TODAY() -> 46256

Sheet D11 Montes de Oca
H1: Montes de Oca | X1: =AVERAGE(L7,L9,L11,L13,L17,L21) -> 1.0347848 | Y1: =1-X1 -> -0.034784802
H4: Tipo | I4: Distrito | J4: Meta | K4: Contabilidad | L4: % Avance | M4: Pendiente
H5: Comunidad
I7: San Pedro | J7: 168 | K7: 180 | L7: =K7/J7 -> 1.0714286 | M7: =J7-K7 -> -12
I9: Sabanilla | J9: 88 | K9: 90 | L9: =K9/J9 -> 1.0227273 | M9: =J9-K9 -> -2
I11: Mercedes | J11: 38 | K11: 40 | L11: =K11/J11 -> 1.0526316 | M11: =J11-K11 -> -2
I13: San Rafael | J13: 88 | K13: 96 | L13: =K13/J13 -> 1.0909091 | M13: =J13-K13 -> -8
H15: Comercio
I17: Montes de Oca | J17: 261 | K17: 250 | L17: =K17/J17 -> 0.95785441 | M17: =J17-K17 -> 11
H19: Policial
I21: Montes de Oca | J21: 76 | K21: 77 | L21: =K21/J21 -> 1.0131579 | M21: =J21-K21 -> -1
I24: =TODAY() -> 46256

Sheet D12 Goicochea
H1: Goicochea | X1: =AVERAGE(L7,L9,L11,L13,L15,L17,L19,L23,L27) -> 1.50239 | Y1: =1-X1 -> -0.50239005
H4: Tipo | I4: Distrito | J4: Meta | K4: Contabilidad | L4: % Avance | M4: Pendiente
H5: Comunidad
I7: Guadalupe | J7: 57 | K7: 69 | L7: =K7/J7 -> 1.2105263 | M7: =J7-K7 -> -12
I9: San Francisco | J9: 7 | K9: 16 | L9: =K9/J9 -> 2.2857143 | M9: =J9-K9 -> -9
I11: Calle Blancos | J11: 64 | K11: 69 | L11: =K11/J11 -> 1.078125 | M11: =J11-K11 -> -5
I13: Mata Platano | J13: 58 | K13: 63 | L13: =K13/J13 -> 1.0862069 | M13: =J13-K13 -> -5
I15: Ipis | J15: 88 | K15: 120 | L15: =K15/J15 -> 1.3636364 | M15: =J15-K15 -> -32
I17: Rancho Redondo | J17: 9 | K17: 31 | L17: =K17/J17 -> 3.4444444 | M17: =J17-K17 -> -22
I19: Purral | J19: 100 | K19: 101 | L19: =K19/J19 -> 1.01 | M19: =J19-K19 -> -1
H21: Comercio
I23: Goicochea | J23: 246 | K23: 246 | L23: =K23/J23 -> 1 | M23: =J23-K23 -> 0
H25: Policial
I27: Goicochea | J27: 70 | K27: 73 | L27: =K27/J27 -> 1.0428571 | M27: =J27-K27 -> -3
I30: =TODAY() -> 46256

Sheet D13 Moravia
H1: Moravia | X1: =AVERAGE(L7,L9,L11,L13,L17,L21) -> 1.3362505 | Y1: =1-X1 -> -0.33625048
H4: Tipo | I4: Distrito | J4: Meta | K4: Contabilidad | L4: % Avance | M4: Pendiente
H5: Comunidad
I7: San Vicente | J7: 177 | K7: 199 | L7: =K7/J7 -> 1.1242938 | M7: =J7-K7 -> -22
I9: San Jeronimo | J9: 45 | K9: 57 | L9: =K9/J9 -> 1.2666667 | M9: =J9-K9 -> -12
I11: Paracito | J11: 17 | K11: 38 | L11: =K11/J11 -> 2.2352941 | M11: =J11-K11 -> -21
I13: Trinidad | J13: 142 | K13: 186 | L13: =K13/J13 -> 1.3098592 | M13: =J13-K13 -> -44
H15: Comercio
I17: Moravia | J17: 184 | K17: 190 | L17: =K17/J17 -> 1.0326087 | M17: =J17-K17 -> -6
H19: Policial
I21: Moravia | J21: 41 | K21: 43 | L21: =K21/J21 -> 1.0487805 | M21: =J21-K21 -> -2
I24: =TODAY() -> 46256

Sheet D14 Tibas
H1: Tibas | X1: =AVERAGE(L7,L9,L11,L13,L15,L19,L23) -> 1.2473862 | Y1: =1-X1 -> -0.24738624
H4: Tipo | I4: Distrito | J4: Meta | K4: Contabilidad | L4: % Avance | M4: Pendiente
H5: Comunidad
I7: San Juan | J7: 109 | K7: 117 | L7: =K7/J7 -> 1.0733945 | M7: =J7-K7 -> -8
I9: Cinco Esquinas | J9: 39 | K9: 55 | L9: =K9/J9 -> 1.4102564 | M9: =J9-K9 -> -16
I11: Anaselmo Llorente | J11: 58 | K11: 102 | L11: =K11/J11 -> 1.7586207 | M11: =J11-K11 -> -44
I13: Leon Xlll | J13: 95 | K13: 99 | L13: =K13/J13 -> 1.0421053 | M13: =J13-K13 -> -4
I15: Colima | J15: 82 | K15: 113 | L15: =K15/J15 -> 1.3780488 | M15: =J15-K15 -> -31
H17: Comercio
I19: Tibas | J19: 210 | K19: 211 | L19: =K19/J19 -> 1.0047619 | M19: =J19-K19 -> -1
H21: Policial
I23: Tibas | J23: 62 | K23: 66 | L23: =K23/J23 -> 1.0645161 | M23: =J23-K23 -> -4
I26: =TODAY() -> 46256

Sheet D15 Coronado
H1: Coronado | X1: =AVERAGE(L7,L9,L11,L13,L15,L19,L23) -> 1.0797179 | Y1: =1-X1 -> -0.079717926
H4: Tipo | I4: Distrito | J4: Meta | K4: Contabilidad | L4: % Avance | M4: Pendiente
H5: Comunidad
I7: San Isidro | J7: 92 | K7: 130 | L7: =K7/J7 -> 1.4130435 | M7: =J7-K7 -> -38
I9: San Rafael | J9: 46 | K9: 41 | L9: =K9/J9 -> 0.89130435 | M9: =J9-K9 -> 5
I11: Dulce Nombre | J11: 65 | K11: 72 | L11: =K11/J11 -> 1.1076923 | M11: =J11-K11 -> -7
I13: Patalillo | J13: 133 | K13: 168 | L13: =K13/J13 -> 1.2631579 | M13: =J13-K13 -> -35
I15: Cascajal | J15: 46 | K15: 49 | L15: =K15/J15 -> 1.0652174 | M15: =J15-K15 -> -3
H17: Comercio
I19: Coronado | J19: 159 | K19: 130 | L19: =K19/J19 -> 0.81761006 | M19: =J19-K19 -> 29
H21: Policial
I23: Coronado | J23: 50 | K23: 50 | L23: =K23/J23 -> 1 | M23: =J23-K23 -> 0
I26: =TODAY() -> 46256

Sheet D16 Desamparados N
H1: Desamparados Norte | X1: =AVERAGE(L7,L9,L11,L13,L15,L17,L19,L21,L25,L29) -> 1.0754453 | Y1: =1-X1 -> -0.075445326
H4: Tipo | I4: Distrito | J4: Meta | K4: Contabilidad | L4: % Avance | M4: Pendiente
H5: Comunidad
I7: Desamparados | J7: 83 | K7: 83 | L7: =K7/J7 -> 1 | M7: =J7-K7 -> 0
I9: Patarra | J9: 35 | K9: 41 | L9: =K9/J9 -> 1.1714286 | M9: =J9-K9 -> -6
I11: Damas | J11: 37 | K11: 38 | L11: =K11/J11 -> 1.027027 | M11: =J11-K11 -> -1
I13: Gravilias | J13: 40 | K13: 41 | L13: =K13/J13 -> 1.025 | M13: =J13-K13 -> -1
I15: San Juan de Dios | J15: 58 | K15: 63 | L15: =K15/J15 -> 1.0862069 | M15: =J15-K15 -> -5
I17: San Rafael Arriba | J17: 43 | K17: 48 | L17: =K17/J17 -> 1.1162791 | M17: =J17-K17 -> -5
I19: San Rafael Abajo | J19: 60 | K19: 75 | L19: =K19/J19 -> 1.25 | M19: =J19-K19 -> -15
I21: San Antonio | J21: 27 | K21: 28 | L21: =K21/J21 -> 1.037037 | M21: =J21-K21 -> -1
H23: Comercio
I25: Desamparados N | J25: 217 | K25: 226 | L25: =K25/J25 -> 1.0414747 | M25: =J25-K25 -> -9
H27: Policial
I29: Desamparados N | J29: 103 | K29: 103 | L29: =K29/J29 -> 1 | M29: =J29-K29 -> 0
I32: =TODAY() -> 46256

Sheet D17 Desamparados S
H1: Desamparados Sur | X1: =AVERAGE(L7,L9,L11,L13,L15,L19,L23) -> 1.1465287 | Y1: =1-X1 -> -0.14652872
H4: Tipo | I4: Distrito | J4: Meta | K4: Contabilidad | L4: % Avance | M4: Pendiente
H5: Comunidad
I7: San Cristobal | J7: 21 | K7: 26 | L7: =K7/J7 -> 1.2380952 | M7: =J7-K7 -> -5
I9: Rosario | J9: 17 | K9: 23 | L9: =K9/J9 -> 1.3529412 | M9: =J9-K9 -> -6
I11: Los Guido | J11: 145 | K11: 169 | L11: =K11/J11 -> 1.1655172 | M11: =J11-K11 -> -24
I13: Frailes | J13: 21 | K13: 22 | L13: =K13/J13 -> 1.047619 | M13: =J13-K13 -> -1
I15: San Miguel | J15: 179 | K15: 182 | L15: =K15/J15 -> 1.0167598 | M15: =J15-K15 -> -3
H17: Comercio
I19: Desamparados S | J19: 93 | K19: 108 | L19: =K19/J19 -> 1.1612903 | M19: =J19-K19 -> -15
H21: Policial
I23: Desamparados S | J23: 69 | K23: 72 | L23: =K23/J23 -> 1.0434783 | M23: =J23-K23 -> -3
I26: =TODAY() -> 46256

Sheet D18 Aserri
H1: Aserri | X1: =AVERAGE(L7,L9,L11,L13,L15,L17,L19,L23,L27) -> 1.6544534 | Y1: =1-X1 -> -0.65445338
H4: Tipo | I4: Distrito | J4: Meta | K4: Contabilidad | L4: % Avance | M4: Pendiente
H5: Comunidad
I7: Aserri | J7: 176 | K7: 202 | L7: =K7/J7 -> 1.1477273 | M7: =J7-K7 -> -26
I9: Tarbaca | J9: 10 | K9: 13 | L9: =K9/J9 -> 1.3 | M9: =J9-K9 -> -3
I11: Vuelta Jorco | J11: 44 | K11: 121 | L11: =K11/J11 -> 2.75 | M11: =J11-K11 -> -77
I13: San Gabriel | J13: 41 | K13: 44 | L13: =K13/J13 -> 1.0731707 | M13: =J13-K13 -> -3
I15: Legua | J15: 10 | K15: 13 | L15: =K15/J15 -> 1.3 | M15: =J15-K15 -> -3
I17: Monterrey | J17: 4 | K17: 17 | L17: =K17/J17 -> 4.25 | M17: =J17-K17 -> -13
I19: Salitrillos | J19: 96 | K19: 96 | L19: =K19/J19 -> 1 | M19: =J19-K19 -> 0
H21: Comercio
I23: Aserri | J23: 159 | K23: 170 | L23: =K23/J23 -> 1.0691824 | M23: =J23-K23 -> -11
H25: Policial
I27: Aserri | J27: 70 | K27: 70 | L27: =K27/J27 -> 1 | M27: =J27-K27 -> 0
I30: =TODAY() -> 46256

Sheet D19 Acosta
H1: Acosta | X1: =AVERAGE(L7,L9,L11,L13,L15,L19,L23) -> 1.0303037 | Y1: =1-X1 -> -0.030303686
H4: Tipo | I4: Distrito | J4: Meta | K4: Contabilidad | L4: % Avance | M4: Pendiente
H5: Comunidad
I7: San Ignacio | J7: 157 | K7: 171 | L7: =K7/J7 -> 1.089172 | M7: =J7-K7 -> -14
I9: Guaitil | J9: 47 | K9: 47 | L9: =K9/J9 -> 1 | M9: =J9-K9 -> 0
I11: Palmichal | J11: 92 | K11: 94 | L11: =K11/J11 -> 1.0217391 | M11: =J11-K11 -> -2
I13: Cangrejal | J13: 36 | K13: 37 | L13: =K13/J13 -> 1.0277778 | M13: =J13-K13 -> -1
I15: Sabanillas | J15: 46 | K15: 46 | L15: =K15/J15 -> 1 | M15: =J15-K15 -> 0
H17: Comercio
I19: Acosta | J19: 159 | K19: 166 | L19: =K19/J19 -> 1.0440252 | M19: =J19-K19 -> -7
H21: Policial
I23: Acosta | J23: 68 | K23: 70 | L23: =K23/J23 -> 1.0294118 | M23: =J23-K23 -> -2
I26: =TODAY() -> 46256

Sheet D20 Alajuelita
H1: Alajuelita | X1: =AVERAGE(L7,L9,L11,L13,L15,L19,L23) -> 1.3657517 | Y1: =1-X1 -> -0.36575173
H4: Tipo | I4: Distrito | J4: Meta | K4: Contabilidad | L4: % Avance | M4: Pendiente
H5: Comunidad
I7: Alajuelita | J7: 49 | K7: 86 | L7: =K7/J7 -> 1.755102 | M7: =J7-K7 -> -37
I9: San Josecito | J9: 52 | K9: 91 | L9: =K9/J9 -> 1.75 | M9: =J9-K9 -> -39
I11: San Antonio | J11: 24 | K11: 25 | L11: =K11/J11 -> 1.0416667 | M11: =J11-K11 -> -1
I13: Concepcion | J13: 33 | K13: 54 | L13: =K13/J13 -> 1.6363636 | M13: =J13-K13 -> -21
I15: San Felipe | J15: 165 | K15: 221 | L15: =K15/J15 -> 1.3393939 | M15: =J15-K15 -> -56
H17: Comercio
I19: Alajuelita | J19: 159 | K19: 165 | L19: =K19/J19 -> 1.0377358 | M19: =J19-K19 -> -6
H21: Policial
I23: Alajuelita | J23: 157 | K23: 157 | L23: =K23/J23 -> 1 | M23: =J23-K23 -> 0
I26: =TODAY() -> 46256

Sheet D21 Escazu
H1: Escazu | X1: =AVERAGE(L7,L9,L11,L15,L19) -> 1.0262021 | Y1: =1-X1 -> -0.026202091
H4: Tipo | I4: Distrito | J4: Meta | K4: Contabilidad | L4: % Avance | M4: Pendiente
H5: Comunidad
I7: Escazu | J7: 70 | K7: 74 | L7: =K7/J7 -> 1.0571429 | M7: =J7-K7 -> -4
I9: San Antonio | J9: 154 | K9: 154 | L9: =K9/J9 -> 1 | M9: =J9-K9 -> 0
I11: San Rafael | J11: 159 | K11: 159 | L11: =K11/J11 -> 1 | M11: =J11-K11 -> 0
H13: Comercio
I15: Escazu | J15: 287 | K15: 300 | L15: =K15/J15 -> 1.0452962 | M15: =J15-K15 -> -13
H17: Policial
I19: Escazu | J19: 70 | K19: 72 | L19: =K19/J19 -> 1.0285714 | M19: =J19-K19 -> -2
I22: =TODAY() -> 46256

Sheet D22 Santa Ana
H1: Santa Ana | X1: =AVERAGE(L7,L9,L11,L13,L15,L17,L21,L25) -> 1.0884836 | Y1: =1-X1 -> -0.088483572
H4: Tipo | I4: Distrito | J4: Meta | K4: Contabilidad | L4: % Avance | M4: Pendiente
H5: Comunidad
I7: Santa Ana | J7: 75 | K7: 76 | L7: =K7/J7 -> 1.0133333 | M7: =J7-K7 -> -1
I9: Salitral | J9: 36 | K9: 42 | L9: =K9/J9 -> 1.1666667 | M9: =J9-K9 -> -6
I11: Pozos | J11: 128 | K11: 157 | L11: =K11/J11 -> 1.2265625 | M11: =J11-K11 -> -29
I13: Uruca | J13: 57 | K13: 63 | L13: =K13/J13 -> 1.1052632 | M13: =J13-K13 -> -6
I15: Piedades | J15: 65 | K15: 65 | L15: =K15/J15 -> 1 | M15: =J15-K15 -> 0
I17: Brasil | J17: 21 | K17: 24 | L17: =K17/J17 -> 1.1428571 | M17: =J17-K17 -> -3
H19: Comercio
I21: Santa Ana | J21: 227 | K21: 228 | L21: =K21/J21 -> 1.0044053 | M21: =J21-K21 -> -1
H23: Policial
I25: Santa Ana | J25: 41 | K25: 43 | L25: =K25/J25 -> 1.0487805 | M25: =J25-K25 -> -2
I28: =TODAY() -> 46256

Sheet D23 Mora
H1: Mora | X1: =AVERAGE(L7,L9,L11,L13,L15,L17,L19,L23,L27) -> 1.1343143 | Y1: =1-X1 -> -0.13431428
H4: Tipo | I4: Distrito | J4: Meta | K4: Contabilidad | L4: % Avance | M4: Pendiente
H5: Comunidad
I7: Colon | J7: 205 | K7: 234 | L7: =K7/J7 -> 1.1414634 | M7: =J7-K7 -> -29
I9: Guayabo | J9: 58 | K9: 62 | L9: =K9/J9 -> 1.0689655 | M9: =J9-K9 -> -4
I11: Tabarcia | J11: 48 | K11: 50 | L11: =K11/J11 -> 1.0416667 | M11: =J11-K11 -> -2
I13: Piedras Negras | J13: 7 | K13: 7 | L13: =K13/J13 -> 1 | M13: =J13-K13 -> 0
I15: Picagres | J15: 13 | K15: 20 | L15: =K15/J15 -> 1.5384615 | M15: =J15-K15 -> -7
I17: Quitirrisi | J17: 29 | K17: 40 | L17: =K17/J17 -> 1.3793103 | M17: =J17-K17 -> -11
I19: Jaris | J19: 21 | K19: 21 | L19: =K19/J19 -> 1 | M19: =J19-K19 -> 0
H21: Comercio
I23: Mora | J23: 77 | K23: 80 | L23: =K23/J23 -> 1.038961 | M23: =J23-K23 -> -3
H25: Policial
I27: Mora | J27: 45 | K27: 45 | L27: =K27/J27 -> 1 | M27: =J27-K27 -> 0
I30: =TODAY() -> 46256

Sheet D24 Puriscal
H1: Puriscal | X1: =AVERAGE(L7,L9,L11,L13,L15,L17,L19,L21,L23,L27,L31) -> 1.2369023 | Y1: =1-X1 -> -0.23690234
H4: Tipo | I4: Distrito | J4: Meta | K4: Contabilidad | L4: % Avance | M4: Pendiente
H5: Comunidad
I7: Santiago | J7: 120 | K7: 120 | L7: =K7/J7 -> 1 | M7: =J7-K7 -> 0
I9: Mercedes Sur | J9: 71 | K9: 87 | L9: =K9/J9 -> 1.2253521 | M9: =J9-K9 -> -16
I11: Barbacoas | J11: 45 | K11: 50 | L11: =K11/J11 -> 1.1111111 | M11: =J11-K11 -> -5
I13: Grifo Alto | J13: 15 | K13: 17 | L13: =K13/J13 -> 1.1333333 | M13: =J13-K13 -> -2
I15: San Rafael | J15: 20 | K15: 48 | L15: =K15/J15 -> 2.4 | M15: =J15-K15 -> -28
I17: Candelaria | J17: 18 | K17: 22 | L17: =K17/J17 -> 1.2222222 | M17: =J17-K17 -> -4
I19: Desamparaditos | J19: 8 | K19: 10 | L19: =K19/J19 -> 1.25 | M19: =J19-K19 -> -2
I21: San Antonio | J21: 47 | K21: 48 | L21: =K21/J21 -> 1.0212766 | M21: =J21-K21 -> -1
I23: Chires | J23: 36 | K23: 44 | L23: =K23/J23 -> 1.2222222 | M23: =J23-K23 -> -8
H25: Comercio
I27: Puriscal | J27: 98 | K27: 100 | L27: =K27/J27 -> 1.0204082 | M27: =J27-K27 -> -2
H29: Policial
I31: Puriscal | J31: 54 | K31: 54 | L31: =K31/J31 -> 1 | M31: =J31-K31 -> 0
I34: =TODAY() -> 46256

Sheet D25 Turrubares
H1: Turrubares | X1: =AVERAGE(L7,L9,L11,L13,L15,L19,L23) -> 1.0587695 | Y1: =1-X1 -> -0.058769489
H4: Tipo | I4: Distrito | J4: Meta | K4: Contabilidad | L4: % Avance | M4: Pendiente
H5: Comunidad
I7: San Pablo | J7: 78 | K7: 91 | L7: =K7/J7 -> 1.1666667 | M7: =J7-K7 -> -13
I9: San Pedro | J9: 45 | K9: 48 | L9: =K9/J9 -> 1.0666667 | M9: =J9-K9 -> -3
I11: San Juan de Mata | J11: 82 | K11: 84 | L11: =K11/J11 -> 1.0243902 | M11: =J11-K11 -> -2
I13: San Luis | J13: 38 | K13: 42 | L13: =K13/J13 -> 1.1052632 | M13: =J13-K13 -> -4
I15: Carara | J15: 122 | K15: 125 | L15: =K15/J15 -> 1.0245902 | M15: =J15-K15 -> -3
H17: Comercio
I19: Turrubares | J19: 9 | K19: 9 | L19: =K19/J19 -> 1 | M19: =J19-K19 -> 0
H21: Policial
I23: Turrubares | J23: 42 | K23: 43 | L23: =K23/J23 -> 1.0238095 | M23: =J23-K23 -> -1
I26: =TODAY() -> 46256

Sheet R2
A1: Delegacion Policial | X1: =AVERAGE(C3:C13) -> 1.0731576 | Y1: =1-X1 -> -0.073157599
A3: D26-Alajuela Sur | C3: ='D26 Alajuela Sur'!X1 -> 1.0923947
A4: D27-Alajuela Norte | C4: ='D27 Alajuela Norte'!X1 -> 1.8687724
A5: D28-San Ramón | C5: ='D28 San Ramon'!X1 -> 1.0459328
A6: D29-Grecia | C6: ='D29 Grecia'!X1 -> 1.1283854
A7: D30-San Mateo | C7: ='D30 San Mateo'!X1 -> 0.72765598
A8: D31-Atenas | C8: ='D31 Atenas'!X1 -> 0.65055022
A9: D32-Naranjo | C9: ='D32 Naranjo'!X1 -> 1.0424162
A10: D33-Palmares | C10: ='D33 Palmares'!X1 -> 0.99438735
A11: D34-Poás | C11: ='D34 Poas'!X1 -> 1.1770298
A12: D35-Orotina | C12: ='D35 Orotina'!X1 -> 1.0479553
A13: D36-Sarchí | C13: ='D36 Sarchi'!X1 -> 1.0292533

Sheet D26 Alajuela Sur
H1: Alajuela Sur | X1: =AVERAGE(L7,L9,L11,L13,L15,L19,L23) -> 1.0923947 | Y1: =1-X1 -> -0.092394746
H4: Tipo | I4: Distrito | J4: Meta | K4: Contabilidad | L4: % Avance | M4: Pendiente
H5: Comunidad
I7: Guacima | J7: 93 | K7: 119 | L7: =K7/J7 -> 1.2795699 | M7: =J7-K7 -> -26
I9: Turrucares | J9: 31 | K9: 32 | L9: =K9/J9 -> 1.0322581 | M9: =J9-K9 -> -1
I11: San Rafael | J11: 118 | K11: 132 | L11: =K11/J11 -> 1.1186441 | M11: =J11-K11 -> -14
I13: Garita | J13: 33 | K13: 51 | L13: =K13/J13 -> 1.5454545 | M13: =J13-K13 -> -18
I15: San Antonio | J15: 109 | K15: 95 | L15: =K15/J15 -> 0.87155963 | M15: =J15-K15 -> 14
H17: Comercio
I19: Alajuela S | J19: 219 | K19: 172 | L19: =K19/J19 -> 0.78538813 | M19: =J19-K19 -> 47
H21: Policial
I23: Alajuela S | J23: 72 | K23: 73 | L23: =K23/J23 -> 1.0138889 | M23: =J23-K23 -> -1
I26: =TODAY() -> 46256

Sheet D27 Alajuela Norte
H1: Alajuela Norte | X1: =AVERAGE(L7,L9,L11,L13,L15,L17,L19,L21,L25,L29) -> 1.8687724 | Y1: =1-X1 -> -0.86877244
H4: Tipo | I4: Distrito | J4: Meta | K4: Contabilidad | L4: % Avance | M4: Pendiente
H5: Comunidad
I7: Alajuela | J7: 84 | K7: 120 | L7: =K7/J7 -> 1.4285714 | M7: =J7-K7 -> -36
I9: Carrizal | J9: 17 | K9: 99 | L9: =K9/J9 -> 5.8235294 | M9: =J9-K9 -> -82
I11: San Jose | J11: 100 | K11: 187 | L11: =K11/J11 -> 1.87 | M11: =J11-K11 -> -87
I13: San Isidro | J13: 43 | K13: 60 | L13: =K13/J13 -> 1.3953488 | M13: =J13-K13 -> -17
I15: Sabanilla | J15: 24 | K15: 59 | L15: =K15/J15 -> 2.4583333 | M15: =J15-K15 -> -35
I17: Rio Segundo | J17: 26 | K17: 30 | L17: =K17/J17 -> 1.1538462 | M17: =J17-K17 -> -4
I19: Desamparados | J19: 63 | K19: 72 | L19: =K19/J19 -> 1.1428571 | M19: =J19-K19 -> -9
I21: Tambor | J21: 28 | K21: 54 | L21: =K21/J21 -> 1.9285714 | M21: =J21-K21 -> -26
H23: Comercio
I25: Alajuela N | J25: 300 | K25: 146 | L25: =K25/J25 -> 0.48666667 | M25: =J25-K25 -> 154
H27: Policial
I29: Alajuela N | J29: 132 | K29: 132 | L29: =K29/J29 -> 1 | M29: =J29-K29 -> 0
I32: =TODAY() -> 46256

Sheet D28 San Ramon
H1: San Ramon | X1: =AVERAGE(L7,L9,L11,L13,L15,L17,L19,L21,L23,L25,L27,L29,L33,L37) -> 1.0459328 | Y1: =1-X1 -> -0.045932808
H4: Tipo | I4: Distrito | J4: Meta | K4: Contabilidad | L4: % Avance | M4: Pendiente
H5: Comunidad
I7: San Ramon | J7: 43 | K7: 45 | L7: =K7/J7 -> 1.0465116 | M7: =J7-K7 -> -2
I9: Santiago | J9: 29 | K9: 21 | L9: =K9/J9 -> 0.72413793 | M9: =J9-K9 -> 8
I11: San Juan | J11: 67 | K11: 59 | L11: =K11/J11 -> 0.88059701 | M11: =J11-K11 -> 8
I13: Piedades Norte | J13: 49 | K13: 28 | L13: =K13/J13 -> 0.57142857 | M13: =J13-K13 -> 21
I15: Piedades Sur | J15: 23 | K15: 40 | L15: =K15/J15 -> 1.7391304 | M15: =J15-K15 -> -17
I17: San Rafael | J17: 56 | K17: 46 | L17: =K17/J17 -> 0.82142857 | M17: =J17-K17 -> 10
I19: San Isidro | J19: 30 | K19: 49 | L19: =K19/J19 -> 1.6333333 | M19: =J19-K19 -> -19
I21: Angeles | J21: 13 | K21: 17 | L21: =K21/J21 -> 1.3076923 | M21: =J21-K21 -> -4
I23: Alfaro | J23: 43 | K23: 44 | L23: =K23/J23 -> 1.0232558 | M23: =J23-K23 -> -1
I25: Volio | J25: 14 | K25: 13 | L25: =K25/J25 -> 0.92857143 | M25: =J25-K25 -> 1
I27: Concepcion | J27: 13 | K27: 18 | L27: =K27/J27 -> 1.3846154 | M27: =J27-K27 -> -5
I29: Zapotal | J29: 3 | K29: 3 | L29: =K29/J29 -> 1 | M29: =J29-K29 -> 0
H31: Comercio
I33: San Ramon | J33: 213 | K33: 167 | L33: =K33/J33 -> 0.78403756 | M33: =J33-K33 -> 46
H35: Policial
I37: San Ramon | J37: 119 | K37: 95 | L37: =K37/J37 -> 0.79831933 | M37: =J37-K37 -> 24
I40: =TODAY() -> 46256

Sheet D29 Grecia
H1: Grecia | X1: =AVERAGE(L7,L9,L11,L13,L15,L17,L19,L23,L27) -> 1.1283854 | Y1: =1-X1 -> -0.12838545
H4: Tipo | I4: Distrito | J4: Meta | K4: Contabilidad | L4: % Avance | M4: Pendiente
H5: Comunidad
I7: Grecia | J7: 73 | K7: 102 | L7: =K7/J7 -> 1.3972603 | M7: =J7-K7 -> -29
I9: San Isidro | J9: 36 | K9: 46 | L9: =K9/J9 -> 1.2777778 | M9: =J9-K9 -> -10
I11: San Jose | J11: 50 | K11: 72 | L11: =K11/J11 -> 1.44 | M11: =J11-K11 -> -22
I13: San Roque | J13: 66 | K13: 66 | L13: =K13/J13 -> 1 | M13: =J13-K13 -> 0
I15: Tacares | J15: 49 | K15: 51 | L15: =K15/J15 -> 1.0408163 | M15: =J15-K15 -> -2
I17: Puente de Piedra | J17: 65 | K17: 66 | L17: =K17/J17 -> 1.0153846 | M17: =J17-K17 -> -1
I19: Bolivar | J19: 44 | K19: 46 | L19: =K19/J19 -> 1.0454545 | M19: =J19-K19 -> -2
H21: Comercio
I23: Grecia | J23: 230 | K23: 230 | L23: =K23/J23 -> 1 | M23: =J23-K23 -> 0
H25: Policial
I27: Grecia | J27: 49 | K27: 46 | L27: =K27/J27 -> 0.93877551 | M27: =J27-K27 -> 3
I30: =TODAY() -> 46256

Sheet D30 San Mateo
H1: San Mateo | X1: =AVERAGE(L7,L9,L11,L13,L17,L21) -> 0.72765598 | Y1: =1-X1 -> 0.27234402
H4: Tipo | I4: Distrito | J4: Meta | K4: Contabilidad | L4: % Avance | M4: Pendiente
H5: Comunidad
I7: San Mateo | J7: 148 | K7: 96 | L7: =K7/J7 -> 0.64864865 | M7: =J7-K7 -> 52
I9: Desmonte | J9: 62 | K9: 20 | L9: =K9/J9 -> 0.32258065 | M9: =J9-K9 -> 42
I11: Jesus Maria | J11: 79 | K11: 24 | L11: =K11/J11 -> 0.30379747 | M11: =J11-K11 -> 55
I13: Labrador | J13: 77 | K13: 77 | L13: =K13/J13 -> 1 | M13: =J13-K13 -> 0
H15: Comercio
I17: San Mateo | J17: 19 | K17: 19 | L17: =K17/J17 -> 1 | M17: =J17-K17 -> 0
H19: Policial
I21: San Mateo | J21: 22 | K21: 24 | L21: =K21/J21 -> 1.0909091 | M21: =J21-K21 -> -2
I24: =TODAY() -> 46256

Sheet D31 Atenas
H1: Atenas | X1: =AVERAGE(L7,L9,L11,L13,L15,L17,L19,L21,L25,L29) -> 0.65055022 | Y1: =1-X1 -> 0.34944978
H4: Tipo | I4: Distrito | J4: Meta | K4: Contabilidad | L4: % Avance | M4: Pendiente
H5: Comunidad
I7: Atenas | J7: 97 | K7: 77 | L7: =K7/J7 -> 0.79381443 | M7: =J7-K7 -> 20
I9: Jesus | J9: 57 | K9: 67 | L9: =K9/J9 -> 1.1754386 | M9: =J9-K9 -> -10
I11: Mercedes | J11: 50 | K11: 34 | L11: =K11/J11 -> 0.68 | M11: =J11-K11 -> 16
I13: San Isidro | J13: 46 | K13: 25 | L13: =K13/J13 -> 0.54347826 | M13: =J13-K13 -> 21
I15: Concepcion | J15: 55 | K15: 11 | L15: =K15/J15 -> 0.2 | M15: =J15-K15 -> 44
I17: San Jose | J17: 30 | K17: 13 | L17: =K17/J17 -> 0.43333333 | M17: =J17-K17 -> 17
I19: Santa Eulalia | J19: 33 | K19: 9 | L19: =K19/J19 -> 0.27272727 | M19: =J19-K19 -> 24
I21: Escobal | J21: 13 | K21: 14 | L21: =K21/J21 -> 1.0769231 | M21: =J21-K21 -> -1
H23: Comercio
I25: Atenas | J25: 94 | K25: 31 | L25: =K25/J25 -> 0.32978723 | M25: =J25-K25 -> 63
H27: Policial
I29: Atenas | J29: 30 | K29: 30 | L29: =K29/J29 -> 1 | M29: =J29-K29 -> 0
I32: =TODAY() -> 46256

Sheet D32 Naranjo
H1: Naranjo | X1: =AVERAGE(L7,L9,L11,L13,L15,L17,L19,L21,L25,L29) -> 1.0424162 | Y1: =1-X1 -> -0.042416218
H4: Tipo | I4: Distrito | J4: Meta | K4: Contabilidad | L4: % Avance | M4: Pendiente
H5: Comunidad
I7: Naranjo | J7: 128 | K7: 135 | L7: =K7/J7 -> 1.0546875 | M7: =J7-K7 -> -7
I9: San Miguel | J9: 46 | K9: 51 | L9: =K9/J9 -> 1.1086957 | M9: =J9-K9 -> -5
I11: San Jose | J11: 28 | K11: 28 | L11: =K11/J11 -> 1 | M11: =J11-K11 -> 0
I13: Cirri Sur | J13: 43 | K13: 53 | L13: =K13/J13 -> 1.2325581 | M13: =J13-K13 -> -10
I15: San Jeronimo | J15: 32 | K15: 26 | L15: =K15/J15 -> 0.8125 | M15: =J15-K15 -> 6
I17: San Juan | J17: 29 | K17: 38 | L17: =K17/J17 -> 1.3103448 | M17: =J17-K17 -> -9
I19: Rosario | J19: 37 | K19: 39 | L19: =K19/J19 -> 1.0540541 | M19: =J19-K19 -> -2
I21: Palmitos | J21: 39 | K21: 44 | L21: =K21/J21 -> 1.1282051 | M21: =J21-K21 -> -5
H23: Comercio
I25: Naranjo | J25: 175 | K25: 117 | L25: =K25/J25 -> 0.66857143 | M25: =J25-K25 -> 58
H27: Policial
I29: Naranjo | J29: 55 | K29: 58 | L29: =K29/J29 -> 1.0545455 | M29: =J29-K29 -> -3
I32: =TODAY() -> 46256

Sheet D33 Palmares
H1: Palmares | X1: =AVERAGE(L7,L9,L11,L13,L15,L17,L19,L23,L27) -> 0.99438735 | Y1: =1-X1 -> 0.005612647
H4: Tipo | I4: Distrito | J4: Meta | K4: Contabilidad | L4: % Avance | M4: Pendiente
H5: Comunidad
I7: Palmares | J7: 33 | K7: 36 | L7: =K7/J7 -> 1.0909091 | M7: =J7-K7 -> -3
I9: Zaragoza | J9: 91 | K9: 76 | L9: =K9/J9 -> 0.83516484 | M9: =J9-K9 -> 15
I11: Buenos Aires | J11: 81 | K11: 83 | L11: =K11/J11 -> 1.0246914 | M11: =J11-K11 -> -2
I13: Santiago | J13: 31 | K13: 31 | L13: =K13/J13 -> 1 | M13: =J13-K13 -> 0
I15: Candelaria | J15: 23 | K15: 24 | L15: =K15/J15 -> 1.0434783 | M15: =J15-K15 -> -1
I17: Esquipulas | J17: 77 | K17: 72 | L17: =K17/J17 -> 0.93506494 | M17: =J17-K17 -> 5
I19: Granja | J19: 45 | K19: 46 | L19: =K19/J19 -> 1.0222222 | M19: =J19-K19 -> -1
H21: Comercio
I23: Palmares | J23: 124 | K23: 122 | L23: =K23/J23 -> 0.98387097 | M23: =J23-K23 -> 2
H25: Policial
I27: Palmares | J27: 71 | K27: 72 | L27: =K27/J27 -> 1.0140845 | M27: =J27-K27 -> -1
I30: =TODAY() -> 46256

Sheet D34 Poas
H1: Poas | X1: =AVERAGE(L7,L9,L11,L13,L15,L19,L23) -> 1.1770298 | Y1: =1-X1 -> -0.17702979
H4: Tipo | I4: Distrito | J4: Meta | K4: Contabilidad | L4: % Avance | M4: Pendiente
H5: Comunidad
I7: San Pedro | J7: 85 | K7: 95 | L7: =K7/J7 -> 1.1176471 | M7: =J7-K7 -> -10
I9: San Juan | J9: 62 | K9: 63 | L9: =K9/J9 -> 1.016129 | M9: =J9-K9 -> -1
I11: San Rafael | J11: 74 | K11: 75 | L11: =K11/J11 -> 1.0135135 | M11: =J11-K11 -> -1
I13: Carrillos | J13: 126 | K13: 130 | L13: =K13/J13 -> 1.031746 | M13: =J13-K13 -> -4
I15: Sabana Redonda | J15: 34 | K15: 66 | L15: =K15/J15 -> 1.9411765 | M15: =J15-K15 -> -32
H17: Comercio
I19: Poas | J19: 90 | K19: 92 | L19: =K19/J19 -> 1.0222222 | M19: =J19-K19 -> -2
H21: Policial
I23: Poas | J23: 31 | K23: 34 | L23: =K23/J23 -> 1.0967742 | M23: =J23-K23 -> -3
I26: =TODAY() -> 46256

Sheet D35 Orotina
H1: Orotina | X1: =AVERAGE(L7,L9,L11,L13,L15,L19,L23) -> 1.0479553 | Y1: =1-X1 -> -0.047955314
H4: Tipo | I4: Distrito | J4: Meta | K4: Contabilidad | L4: % Avance | M4: Pendiente
H5: Comunidad
I7: Orotina | J7: 158 | K7: 162 | L7: =K7/J7 -> 1.0253165 | M7: =J7-K7 -> -4
I9: Mastate | J9: 36 | K9: 37 | L9: =K9/J9 -> 1.0277778 | M9: =J9-K9 -> -1
I11: Hacienda Vieja | J11: 20 | K11: 31 | L11: =K11/J11 -> 1.55 | M11: =J11-K11 -> -11
I13: Coyolar | J13: 123 | K13: 81 | L13: =K13/J13 -> 0.65853659 | M13: =J13-K13 -> 42
I15: Ceiba | J15: 42 | K15: 46 | L15: =K15/J15 -> 1.0952381 | M15: =J15-K15 -> -4
H17: Comercio
I19: Orotina | J19: 69 | K19: 64 | L19: =K19/J19 -> 0.92753623 | M19: =J19-K19 -> 5
H21: Policial
I23: Orotina | J23: 39 | K23: 41 | L23: =K23/J23 -> 1.0512821 | M23: =J23-K23 -> -2
I26: =TODAY() -> 46256

Sheet D36 Sarchi
H1: Sarchi | X1: =AVERAGE(L7,L9,L11,L13,L15,L19,L23) -> 1.0292533 | Y1: =1-X1 -> -0.029253273
H4: Tipo | I4: Distrito | J4: Meta | K4: Contabilidad | L4: % Avance | M4: Pendiente
H5: Comunidad
I7: Sarchí Norte | J7: 134 | K7: 134 | L7: =K7/J7 -> 1 | M7: =J7-K7 -> 0
I9: Sarchi Sur | J9: 112 | K9: 113 | L9: =K9/J9 -> 1.0089286 | M9: =J9-K9 -> -1
I11: Toro Amarillo | J11: 7 | K11: 8 | L11: =K11/J11 -> 1.1428571 | M11: =J11-K11 -> -1
I13: San Pedro | J13: 76 | K13: 79 | L13: =K13/J13 -> 1.0394737 | M13: =J13-K13 -> -3
I15: Rodriguez | J15: 49 | K15: 49 | L15: =K15/J15 -> 1 | M15: =J15-K15 -> 0
H17: Comercio
I19: Sarchi | J19: 74 | K19: 75 | L19: =K19/J19 -> 1.0135135 | M19: =J19-K19 -> -1
H21: Policial
I23: Sarchi | J23: 46 | K23: 46 | L23: =K23/J23 -> 1 | M23: =J23-K23 -> 0
I26: =TODAY() -> 46256

Sheet R3
A1: Delegacion Policial | X1: =AVERAGE(C3:C14) -> 1.1081539 | Y1: =1-X1 -> -0.10815393
A3: D37-Cartago | C3: ='D37 Cartago'!X1 -> 1.3484426
A4: D38-Paraiso | C4: ='D38 Paraiso'!X1 -> 1.4272981
A5: D39-La Unión | C5: ='D39 La Union'!X1 -> 1.0160469
A6: D40-Jiménez | C6: ='D40 Jimenez'!X1 -> 1.1762817
A7: D41-Turrialba | C7: ='D41 Turrialba'!X1 -> 1.1441833
A8: D42-Alvarado | C8: ='D42 Alvarado'!X1 -> 1.0318046
A9: D43-Oreamuno | C9: ='D43 Oreamuno'!X1 -> 1.1072524
A10: D44-El Guarco | C10: ='D44 El Guarco'!X1 -> 1.1350282
A11: D45-Tarrazú | C11: ='D45 Tarrazu'!X1 -> 1.0016327
A12: D46-Dota | C12: ='D46 Dota'!X1 -> 1.026032
A13: D47-León Cortes | C13: ='D47 Leon Cortes'!X1 -> 1.0432887
A14: D48-Guadalupe | C14: ='D48 Guadalupe'!X1 -> 0.84055611

Sheet D37 Cartago
H1: Cartago | X1: =AVERAGE(L7,L9,L11,L13,L15,L17,L19,L21,L25,L29) -> 1.3484426 | Y1: =1-X1 -> -0.3484426
H4: Tipo | I4: Distrito | J4: Meta | K4: Contabilidad | L4: % Avance | M4: Pendiente
H5: Comunidad
I7: Oriental | J7: 34 | K7: 62 | L7: =K7/J7 -> 1.8235294 | M7: =J7-K7 -> -28
I9: Occidental | J9: 30 | K9: 70 | L9: =K9/J9 -> 2.3333333 | M9: =J9-K9 -> -40
I11: Carmen | J11: 57 | K11: 57 | L11: =K11/J11 -> 1 | M11: =J11-K11 -> 0
I13: San Nicolas | J13: 88 | K13: 107 | L13: =K13/J13 -> 1.2159091 | M13: =J13-K13 -> -19
I15: Aguacaliente | J15: 107 | K15: 108 | L15: =K15/J15 -> 1.0093458 | M15: =J15-K15 -> -1
I17: Tierra Blanca | J17: 17 | K17: 27 | L17: =K17/J17 -> 1.5882353 | M17: =J17-K17 -> -10
I19: Dulce Nombre | J19: 35 | K19: 36 | L19: =K19/J19 -> 1.0285714 | M19: =J19-K19 -> -1
I21: Llano Grande | J21: 15 | K21: 22 | L21: =K21/J21 -> 1.4666667 | M21: =J21-K21 -> -7
H23: Comercio
I25: Cartago | J25: 282 | K25: 285 | L25: =K25/J25 -> 1.0106383 | M25: =J25-K25 -> -3
H27: Policial
I29: Cartago | J29: 122 | K29: 123 | L29: =K29/J29 -> 1.0081967 | M29: =J29-K29 -> -1
I32: =TODAY() -> 46256

Sheet D38 Paraiso
H1: Paraiso | X1: =AVERAGE(L7,L9,L11,L13,L15,L17,L21,L25) -> 1.4272981 | Y1: =1-X1 -> -0.42729805
H4: Tipo | I4: Distrito | J4: Meta | K4: Contabilidad | L4: % Avance | M4: Pendiente
H5: Comunidad
I7: Paraiso | J7: 112 | K7: 130 | L7: =K7/J7 -> 1.1607143 | M7: =J7-K7 -> -18
I9: Santiago | J9: 39 | K9: 69 | L9: =K9/J9 -> 1.7692308 | M9: =J9-K9 -> -30
I11: Orosi | J11: 62 | K11: 70 | L11: =K11/J11 -> 1.1290323 | M11: =J11-K11 -> -8
I13: Cachi | J13: 36 | K13: 41 | L13: =K13/J13 -> 1.1388889 | M13: =J13-K13 -> -5
I15: Llanos de Santa Lucia | J15: 119 | K15: 139 | L15: =K15/J15 -> 1.1680672 | M15: =J15-K15 -> -20
I17: Birrisito | J17: 14 | K17: 42 | L17: =K17/J17 -> 3 | M17: =J17-K17 -> -28
H19: Comercio
I21: Paraiso | J21: 120 | K21: 121 | L21: =K21/J21 -> 1.0083333 | M21: =J21-K21 -> -1
H23: Policial
I25: Paraiso | J25: 68 | K25: 71 | L25: =K25/J25 -> 1.0441176 | M25: =J25-K25 -> -3
I28: =TODAY() -> 46256

Sheet D39 La Union
H1: La Union | X1: =AVERAGE(L7,L9,L11,L13,L15,L17,L19,L21,L25,L29) -> 1.0160469 | Y1: =1-X1 -> -0.016046942
H4: Tipo | I4: Distrito | J4: Meta | K4: Contabilidad | L4: % Avance | M4: Pendiente
H5: Comunidad
I7: Tres Rios | J7: 29 | K7: 29 | L7: =K7/J7 -> 1 | M7: =J7-K7 -> 0
I9: San Diego | J9: 85 | K9: 87 | L9: =K9/J9 -> 1.0235294 | M9: =J9-K9 -> -2
I11: San Juan | J11: 53 | K11: 57 | L11: =K11/J11 -> 1.0754717 | M11: =J11-K11 -> -4
I13: San Rafael | J13: 54 | K13: 54 | L13: =K13/J13 -> 1 | M13: =J13-K13 -> 0
I15: Concepcion | J15: 65 | K15: 65 | L15: =K15/J15 -> 1 | M15: =J15-K15 -> 0
I17: Dulce Nombre | J17: 31 | K17: 31 | L17: =K17/J17 -> 1 | M17: =J17-K17 -> 0
I19: San Ramon | J19: 15 | K19: 15 | L19: =K19/J19 -> 1 | M19: =J19-K19 -> 0
I21: Rio Azul | J21: 51 | K21: 52 | L21: =K21/J21 -> 1.0196078 | M21: =J21-K21 -> -1
H23: Comercio
I25: La Union | J25: 215 | K25: 224 | L25: =K25/J25 -> 1.0418605 | M25: =J25-K25 -> -9
H27: Policial
I29: La Union | J29: 61 | K29: 61 | L29: =K29/J29 -> 1 | M29: =J29-K29 -> 0
I32: =TODAY() -> 46256

Sheet D40 Jimenez
H1: Jimenez | X1: =AVERAGE(L7,L9,L11,L13,L17,L21) -> 1.1762817 | Y1: =1-X1 -> -0.17628167
H4: Tipo | I4: Distrito | J4: Meta | K4: Contabilidad | L4: % Avance | M4: Pendiente
H5: Comunidad
I7: Juan Viñas | J7: 123 | K7: 124 | L7: =K7/J7 -> 1.0081301 | M7: =J7-K7 -> -1
I9: La Victoria | J9: 38 | K9: 40 | L9: =K9/J9 -> 1.0526316 | M9: =J9-K9 -> -2
I11: Tucurrique | J11: 131 | K11: 149 | L11: =K11/J11 -> 1.1374046 | M11: =J11-K11 -> -18
I13: Pejibaye | J13: 85 | K13: 85 | L13: =K13/J13 -> 1 | M13: =J13-K13 -> 0
H15: Comercio
I17: Jimenez | J17: 21 | K17: 38 | L17: =K17/J17 -> 1.8095238 | M17: =J17-K17 -> -17
H19: Policial
I21: Jimenez | J21: 60 | K21: 63 | L21: =K21/J21 -> 1.05 | M21: =J21-K21 -> -3
I24: =TODAY() -> 46256

Sheet D41 Turrialba
H1: Turrialba | X1: =AVERAGE(L7,L9,L11,L13,L15,L17,L19,L21,L23,L25,L27,L29,L33,L37) -> 1.1441833 | Y1: =1-X1 -> -0.1441833
H4: Tipo | I4: Distrito | J4: Meta | K4: Contabilidad | L4: % Avance | M4: Pendiente
H5: Comunidad
I7: Turrialba | J7: 139 | K7: 145 | L7: =K7/J7 -> 1.0431655 | M7: =J7-K7 -> -6
I9: La Suiza | J9: 41 | K9: 41 | L9: =K9/J9 -> 1 | M9: =J9-K9 -> 0
I11: Peralta | J11: 3 | K11: 4 | L11: =K11/J11 -> 1.3333333 | M11: =J11-K11 -> -1
I13: Santa Cruz | J13: 21 | K13: 22 | L13: =K13/J13 -> 1.047619 | M13: =J13-K13 -> -1
I15: Santa Teresita | J15: 29 | K15: 33 | L15: =K15/J15 -> 1.137931 | M15: =J15-K15 -> -4
I17: Pavones | J17: 25 | K17: 27 | L17: =K17/J17 -> 1.08 | M17: =J17-K17 -> -2
I19: Tuis | J19: 15 | K19: 16 | L19: =K19/J19 -> 1.0666667 | M19: =J19-K19 -> -1
I21: Tayutic | J21: 13 | K21: 21 | L21: =K21/J21 -> 1.6153846 | M21: =J21-K21 -> -8
I23: Santa Rosa | J23: 31 | K23: 40 | L23: =K23/J23 -> 1.2903226 | M23: =J23-K23 -> -9
I25: Tres Equis | J25: 11 | K25: 15 | L25: =K25/J25 -> 1.3636364 | M25: =J25-K25 -> -4
I27: La Isabel | J27: 33 | K27: 34 | L27: =K27/J27 -> 1.030303 | M27: =J27-K27 -> -1
I29: Chirripo | J29: 22 | K29: 22 | L29: =K29/J29 -> 1 | M29: =J29-K29 -> 0
H31: Comercio
I33: Turrialba | J33: 196 | K33: 198 | L33: =K33/J33 -> 1.0102041 | M33: =J33-K33 -> -2
H35: Policial
I37: Turrialba | J37: 158 | K37: 158 | L37: =K37/J37 -> 1 | M37: =J37-K37 -> 0
I40: =TODAY() -> 46256

Sheet D42 Alvarado
H1: Alvarado | X1: =AVERAGE(L7,L9,L11,L15,L19) -> 1.0318046 | Y1: =1-X1 -> -0.031804613
H4: Tipo | I4: Distrito | J4: Meta | K4: Contabilidad | L4: % Avance | M4: Pendiente
H5: Comunidad
I7: Pacayas | J7: 141 | K7: 141 | L7: =K7/J7 -> 1 | M7: =J7-K7 -> 0
I9: Cervantes | J9: 168 | K9: 168 | L9: =K9/J9 -> 1 | M9: =J9-K9 -> 0
I11: Capellades | J11: 67 | K11: 74 | L11: =K11/J11 -> 1.1044776 | M11: =J11-K11 -> -7
H13: Comercio
I15: Alvarado | J15: 55 | K15: 58 | L15: =K15/J15 -> 1.0545455 | M15: =J15-K15 -> -3
H17: Policial
I19: Alvarado | J19: 37 | K19: 37 | L19: =K19/J19 -> 1 | M19: =J19-K19 -> 0
I22: =TODAY() -> 46256

Sheet D43 Oreamuno
H1: Oreamuno | X1: =AVERAGE(L7,L9,L11,L13,L15,L19,L23) -> 1.1072524 | Y1: =1-X1 -> -0.10725239
H4: Tipo | I4: Distrito | J4: Meta | K4: Contabilidad | L4: % Avance | M4: Pendiente
H5: Comunidad
I7: San Rafael | J7: 216 | K7: 232 | L7: =K7/J7 -> 1.0740741 | M7: =J7-K7 -> -16
I9: Cot | J9: 89 | K9: 91 | L9: =K9/J9 -> 1.0224719 | M9: =J9-K9 -> -2
I11: Potrero Cerrado | J11: 21 | K11: 34 | L11: =K11/J11 -> 1.6190476 | M11: =J11-K11 -> -13
I13: Cipreses | J13: 33 | K13: 43 | L13: =K13/J13 -> 1.3030303 | M13: =J13-K13 -> -10
I15: Santa Rosa | J15: 24 | K15: 24 | L15: =K15/J15 -> 1 | M15: =J15-K15 -> 0
H17: Comercio
I19: Oreamuno | J19: 112 | K19: 82 | L19: =K19/J19 -> 0.73214286 | M19: =J19-K19 -> 30
H21: Policial
I23: Oreamuno | J23: 40 | K23: 40 | L23: =K23/J23 -> 1 | M23: =J23-K23 -> 0
I26: =TODAY() -> 46256

Sheet D44 El Guarco
H1: El Guarco | X1: =AVERAGE(L7,L9,L11,L13,L17,L21) -> 1.1350282 | Y1: =1-X1 -> -0.13502817
H4: Tipo | I4: Distrito | J4: Meta | K4: Contabilidad | L4: % Avance | M4: Pendiente
H5: Comunidad
I7: Tejar | J7: 216 | K7: 249 | L7: =K7/J7 -> 1.1527778 | M7: =J7-K7 -> -33
I9: San Isidro | J9: 96 | K9: 98 | L9: =K9/J9 -> 1.0208333 | M9: =J9-K9 -> -2
I11: Patio de Agua | J11: 4 | K11: 5 | L11: =K11/J11 -> 1.25 | M11: =J11-K11 -> -1
I13: Tobosi | J13: 66 | K13: 87 | L13: =K13/J13 -> 1.3181818 | M13: =J13-K13 -> -21
H15: Comercio
I17: El Guarco | J17: 117 | K17: 125 | L17: =K17/J17 -> 1.0683761 | M17: =J17-K17 -> -8
H19: Policial
I21: El Guarco | J21: 46 | K21: 46 | L21: =K21/J21 -> 1 | M21: =J21-K21 -> 0
I24: =TODAY() -> 46256

Sheet D45 Tarrazu
H1: Tarrazu | X1: =AVERAGE(L7,L9,L11,L15,L19) -> 1.0016327 | Y1: =1-X1 -> -0.0016326758
H4: Tipo | I4: Distrito | J4: Meta | K4: Contabilidad | L4: % Avance | M4: Pendiente
H5: Comunidad
I7: San Marcos | J7: 228 | K7: 224 | L7: =K7/J7 -> 0.98245614 | M7: =J7-K7 -> 4
I9: San Lorenzo | J9: 105 | K9: 96 | L9: =K9/J9 -> 0.91428571 | M9: =J9-K9 -> 9
I11: San Carlos | J11: 43 | K11: 47 | L11: =K11/J11 -> 1.0930233 | M11: =J11-K11 -> -4
H13: Comercio
I15: Tarrazu | J15: 77 | K15: 72 | L15: =K15/J15 -> 0.93506494 | M15: =J15-K15 -> 5
H17: Policial
I19: Tarrazu | J19: 24 | K19: 26 | L19: =K19/J19 -> 1.0833333 | M19: =J19-K19 -> -2
I22: =TODAY() -> 46256

Sheet D46 Dota
H1: Dota | X1: =AVERAGE(L7,L9,L11,L15,L19) -> 1.026032 | Y1: =1-X1 -> -0.026031988
H4: Tipo | I4: Distrito | J4: Meta | K4: Contabilidad | L4: % Avance | M4: Pendiente
H5: Comunidad
I7: Santa Maria | J7: 239 | K7: 237 | L7: =K7/J7 -> 0.9916318 | M7: =J7-K7 -> 2
I9: Jardin | J9: 33 | K9: 36 | L9: =K9/J9 -> 1.0909091 | M9: =J9-K9 -> -3
I11: Copey | J11: 95 | K11: 95 | L11: =K11/J11 -> 1 | M11: =J11-K11 -> 0
H13: Comercio
I15: Dota | J15: 42 | K15: 44 | L15: =K15/J15 -> 1.047619 | M15: =J15-K15 -> -2
H17: Policial
I19: Dota | J19: 20 | K19: 20 | L19: =K19/J19 -> 1 | M19: =J19-K19 -> 0
I22: =TODAY() -> 46256

Sheet D47 Leon Cortes
H1: Leon Cortes | X1: =AVERAGE(L7,L9,L11,L13,L15,L17,L21,L25) -> 1.0432887 | Y1: =1-X1 -> -0.043288679
H4: Tipo | I4: Distrito | J4: Meta | K4: Contabilidad | L4: % Avance | M4: Pendiente
H5: Comunidad
I7: San Pablo | J7: 125 | K7: 128 | L7: =K7/J7 -> 1.024 | M7: =J7-K7 -> -3
I9: San Andres | J9: 47 | K9: 53 | L9: =K9/J9 -> 1.1276596 | M9: =J9-K9 -> -6
I11: Llano Bonito | J11: 60 | K11: 63 | L11: =K11/J11 -> 1.05 | M11: =J11-K11 -> -3
I13: San Isidro | J13: 50 | K13: 51 | L13: =K13/J13 -> 1.02 | M13: =J13-K13 -> -1
I15: Santa Cruz | J15: 58 | K15: 58 | L15: =K15/J15 -> 1 | M15: =J15-K15 -> 0
I17: San Antonio | J17: 34 | K17: 35 | L17: =K17/J17 -> 1.0294118 | M17: =J17-K17 -> -1
H19: Comercio
I21: Leon Cortes | J21: 42 | K21: 46 | L21: =K21/J21 -> 1.0952381 | M21: =J21-K21 -> -4
H23: Policial
I25: Leon Cortes | J25: 26 | K25: 26 | L25: =K25/J25 -> 1 | M25: =J25-K25 -> 0
I28: =TODAY() -> 46256

Sheet D48 Guadalupe
H1: Guadalupe | X1: =AVERAGE(L7,L9,L11,L15,L19) -> 0.84055611 | Y1: =1-X1 -> 0.15944389
H4: Tipo | I4: Distrito | J4: Meta | K4: Contabilidad | L4: % Avance | M4: Pendiente
H5: Comunidad
I7: Guadalupe | J7: 182 | K7: 153 | L7: =K7/J7 -> 0.84065934 | M7: =J7-K7 -> 29
I9: Corralillo | J9: 132 | K9: 95 | L9: =K9/J9 -> 0.71969697 | M9: =J9-K9 -> 37
I11: Quebradilla | J11: 66 | K11: 60 | L11: =K11/J11 -> 0.90909091 | M11: =J11-K11 -> 6
H13: Comercio
I15: Guadalupe | J15: 105 | K15: 77 | L15: =K15/J15 -> 0.73333333 | M15: =J15-K15 -> 28
H17: Policial
I19: Guadalupe | J19: 47 | K19: 47 | L19: =K19/J19 -> 1 | M19: =J19-K19 -> 0
I22: =TODAY() -> 46256

Sheet R4
A1: Delegacion Policial | X1: =AVERAGE(C3:C11) -> 1.1661944 | Y1: =1-X1 -> -0.16619444
A3: D49-Heredia | C3: ='D49 Heredia'!X1 -> 1.6450385
A4: D50-Barva | C4: ='D50 Barva'!X1 -> 1.0117038
A5: D51-Santo Domingo | C5: ='D51 Santo Domingo'!X1 -> 1.1445516
A6: D52-Santa Bárbara | C6: ='D52 Santa Barbara'!X1 -> 1.2155086
A7: D53- San Rafael | C7: ='D53 San Rafael'!X1 -> 1.105523
A8: D54- San Isidro | C8: ='D54 San Isidro'!X1 -> 1.226706
A9: D55- Belén | C9: ='D55 Belen'!X1 -> 1.0208812
A10: D56- Flores | C10: ='D56 Flores'!X1 -> 1.0712931
A11: D57- San Pablo | C11: ='D57 San Pablo'!X1 -> 1.054544

Sheet D49 Heredia
H1: Heredia | X1: =AVERAGE(L7,L9,L11,L13,L15,L19,L23) -> 1.6450385 | Y1: =1-X1 -> -0.64503855
H4: Tipo | I4: Distrito | J4: Meta | K4: Contabilidad | L4: % Avance | M4: Pendiente
H5: Comunidad
I7: Heredia | J7: 46 | K7: 47 | L7: =K7/J7 -> 1.0217391 | M7: =J7-K7 -> -1
I9: Mercedes | J9: 80 | K9: 157 | L9: =K9/J9 -> 1.9625 | M9: =J9-K9 -> -77
I11: San Francisco | J11: 160 | K11: 163 | L11: =K11/J11 -> 1.01875 | M11: =J11-K11 -> -3
I13: Ulloa | J13: 95 | K13: 207 | L13: =K13/J13 -> 2.1789474 | M13: =J13-K13 -> -112
I15: Vara Blanca | J15: 3 | K15: 10 | L15: =K15/J15 -> 3.3333333 | M15: =J15-K15 -> -7
H17: Comercio
I19: Heredia | J19: 337 | K19: 337 | L19: =K19/J19 -> 1 | M19: =J19-K19 -> 0
H21: Policial
I23: Heredia | J23: 120 | K23: 120 | L23: =K23/J23 -> 1 | M23: =J23-K23 -> 0
I26: =TODAY() -> 46256

Sheet D50 Barva
H1: Barva | X1: =AVERAGE(L7,L9,L11,L13,L15,L17,L19,L23,L27) -> 1.0117038 | Y1: =1-X1 -> -0.011703795
H4: Tipo | I4: Distrito | J4: Meta | K4: Contabilidad | L4: % Avance | M4: Pendiente
H5: Comunidad
I7: Barva | J7: 37 | K7: 44 | L7: =K7/J7 -> 1.1891892 | M7: =J7-K7 -> -7
I9: San Pedro | J9: 58 | K9: 40 | L9: =K9/J9 -> 0.68965517 | M9: =J9-K9 -> 18
I11: San Pablo | J11: 81 | K11: 82 | L11: =K11/J11 -> 1.0123457 | M11: =J11-K11 -> -1
I13: San Roque | J13: 44 | K13: 45 | L13: =K13/J13 -> 1.0227273 | M13: =J13-K13 -> -1
I15: Puente Salas | J15: 38 | K15: 40 | L15: =K15/J15 -> 1.0526316 | M15: =J15-K15 -> -2
I17: Santa Lucia | J17: 68 | K17: 75 | L17: =K17/J17 -> 1.1029412 | M17: =J17-K17 -> -7
I19: San Jose de la Montaña | J19: 56 | K19: 79 | L19: =K19/J19 -> 1.4107143 | M19: =J19-K19 -> -23
H21: Comercio
I23: Barva | J23: 107 | K23: 55 | L23: =K23/J23 -> 0.51401869 | M23: =J23-K23 -> 52
H25: Policial
I27: Barva | J27: 27 | K27: 30 | L27: =K27/J27 -> 1.1111111 | M27: =J27-K27 -> -3
I30: =TODAY() -> 46256

Sheet D51 Santo Domingo
H1: Santo Domingo | X1: =AVERAGE(L7,L9,L11,L13,L15,L17,L19,L23,L27) -> 1.1445516 | Y1: =1-X1 -> -0.14455161
H4: Tipo | I4: Distrito | J4: Meta | K4: Contabilidad | L4: % Avance | M4: Pendiente
H5: Comunidad
I7: Santo Domingo | J7: 38 | K7: 58 | L7: =K7/J7 -> 1.5263158 | M7: =J7-K7 -> -20
I9: San Vicente | J9: 66 | K9: 79 | L9: =K9/J9 -> 1.1969697 | M9: =J9-K9 -> -13
I11: San Miguel | J11: 65 | K11: 68 | L11: =K11/J11 -> 1.0461538 | M11: =J11-K11 -> -3
I13: Santo Tomas | J13: 65 | K13: 85 | L13: =K13/J13 -> 1.3076923 | M13: =J13-K13 -> -20
I15: Santa Rosa | J15: 76 | K15: 83 | L15: =K15/J15 -> 1.0921053 | M15: =J15-K15 -> -7
I17: Tures | J17: 37 | K17: 37 | L17: =K17/J17 -> 1 | M17: =J17-K17 -> 0
I19: Pará | J19: 35 | K19: 39 | L19: =K19/J19 -> 1.1142857 | M19: =J19-K19 -> -4
H21: Comercio
I23: Santo Domingo | J23: 172 | K23: 175 | L23: =K23/J23 -> 1.0174419 | M23: =J23-K23 -> -3
H25: Policial
I27: Santo Domingo | J27: 41 | K27: 41 | L27: =K27/J27 -> 1 | M27: =J27-K27 -> 0
I30: =TODAY() -> 46256

Sheet D52 Santa Barbara
H1: Santa Barbara | X1: =AVERAGE(L7,L9,L11,L13,L15,L17,L21,L25) -> 1.2155086 | Y1: =1-X1 -> -0.21550861
H4: Tipo | I4: Distrito | J4: Meta | K4: Contabilidad | L4: % Avance | M4: Pendiente
H5: Comunidad
I7: Santa Barbara | J7: 52 | K7: 52 | L7: =K7/J7 -> 1 | M7: =J7-K7 -> 0
I9: San Pedro | J9: 61 | K9: 62 | L9: =K9/J9 -> 1.0163934 | M9: =J9-K9 -> -1
I11: San Juan | J11: 83 | K11: 89 | L11: =K11/J11 -> 1.0722892 | M11: =J11-K11 -> -6
I13: Jesus | J13: 103 | K13: 133 | L13: =K13/J13 -> 1.2912621 | M13: =J13-K13 -> -30
I15: Santo Domingo | J15: 32 | K15: 63 | L15: =K15/J15 -> 1.96875 | M15: =J15-K15 -> -31
I17: Puraba | J17: 49 | K17: 54 | L17: =K17/J17 -> 1.1020408 | M17: =J17-K17 -> -5
H19: Comercio
I21: Santa Barbara | J21: 150 | K21: 161 | L21: =K21/J21 -> 1.0733333 | M21: =J21-K21 -> -11
H23: Policial
I25: Santa Barbara | J25: 35 | K25: 42 | L25: =K25/J25 -> 1.2 | M25: =J25-K25 -> -7
I28: =TODAY() -> 46256

Sheet D53 San Rafael
H1: San Rafael | X1: =AVERAGE(L7,L9,L11,L13,L15,L19,L23) -> 1.105523 | Y1: =1-X1 -> -0.10552304
H4: Tipo | I4: Distrito | J4: Meta | K4: Contabilidad | L4: % Avance | M4: Pendiente
H5: Comunidad
I7: San Rafael | J7: 69 | K7: 70 | L7: =K7/J7 -> 1.0144928 | M7: =J7-K7 -> -1
I9: San Josecito | J9: 98 | K9: 103 | L9: =K9/J9 -> 1.0510204 | M9: =J9-K9 -> -5
I11: Santiago | J11: 72 | K11: 77 | L11: =K11/J11 -> 1.0694444 | M11: =J11-K11 -> -5
I13: Angeles | J13: 90 | K13: 91 | L13: =K13/J13 -> 1.0111111 | M13: =J13-K13 -> -1
I15: Concepcion | J15: 54 | K15: 63 | L15: =K15/J15 -> 1.1666667 | M15: =J15-K15 -> -9
H17: Comercio
I19: San Rafael | J19: 108 | K19: 154 | L19: =K19/J19 -> 1.4259259 | M19: =J19-K19 -> -46
H21: Policial
I23: San Rafael | J23: 33 | K23: 33 | L23: =K23/J23 -> 1 | M23: =J23-K23 -> 0
I26: =TODAY() -> 46256

Sheet D54 San Isidro
H1: San Isidro | X1: =AVERAGE(L7,L9,L11,L13,L17,L21) -> 1.226706 | Y1: =1-X1 -> -0.22670603
H4: Tipo | I4: Distrito | J4: Meta | K4: Contabilidad | L4: % Avance | M4: Pendiente
H5: Comunidad
I7: San Isidro | J7: 98 | K7: 127 | L7: =K7/J7 -> 1.2959184 | M7: =J7-K7 -> -29
I9: San Jose | J9: 145 | K9: 160 | L9: =K9/J9 -> 1.1034483 | M9: =J9-K9 -> -15
I11: Concepcion | J11: 50 | K11: 95 | L11: =K11/J11 -> 1.9 | M11: =J11-K11 -> -45
I13: San Francisco | J13: 86 | K13: 86 | L13: =K13/J13 -> 1 | M13: =J13-K13 -> 0
H15: Comercio
I17: San Isidro | J17: 92 | K17: 93 | L17: =K17/J17 -> 1.0108696 | M17: =J17-K17 -> -1
H19: Policial
I21: San Isidro | J21: 20 | K21: 21 | L21: =K21/J21 -> 1.05 | M21: =J21-K21 -> -1
I24: =TODAY() -> 46256

Sheet D55 Belen
H1: Belen | X1: =AVERAGE(L7,L9,L11,L15,L19) -> 1.0208812 | Y1: =1-X1 -> -0.020881242
H4: Tipo | I4: Distrito | J4: Meta | K4: Contabilidad | L4: % Avance | M4: Pendiente
H5: Comunidad
I7: San Antonio | J7: 158 | K7: 158 | L7: =K7/J7 -> 1 | M7: =J7-K7 -> 0
I9: Ribera | J9: 113 | K9: 118 | L9: =K9/J9 -> 1.0442478 | M9: =J9-K9 -> -5
I11: Asuncion | J11: 108 | K11: 112 | L11: =K11/J11 -> 1.037037 | M11: =J11-K11 -> -4
H13: Comercio
I15: Belen | J15: 173 | K15: 177 | L15: =K15/J15 -> 1.0231214 | M15: =J15-K15 -> -4
H17: Policial
I19: Belen | J19: 21 | K19: 21 | L19: =K19/J19 -> 1 | M19: =J19-K19 -> 0
I22: =TODAY() -> 46256

Sheet D56 Flores
H1: Flores | X1: =AVERAGE(L7,L9,L11,L15,L19) -> 1.0712931 | Y1: =1-X1 -> -0.071293093
H4: Tipo | I4: Distrito | J4: Meta | K4: Contabilidad | L4: % Avance | M4: Pendiente
H5: Comunidad
I7: San Joaquin | J7: 133 | K7: 133 | L7: =K7/J7 -> 1 | M7: =J7-K7 -> 0
I9: Barrantes | J9: 41 | K9: 51 | L9: =K9/J9 -> 1.2439024 | M9: =J9-K9 -> -10
I11: Llorente | J11: 204 | K11: 207 | L11: =K11/J11 -> 1.0147059 | M11: =J11-K11 -> -3
H13: Comercio
I15: Flores | J15: 112 | K15: 114 | L15: =K15/J15 -> 1.0178571 | M15: =J15-K15 -> -2
H17: Policial
I19: Flores | J19: 25 | K19: 27 | L19: =K19/J19 -> 1.08 | M19: =J19-K19 -> -2
I22: =TODAY() -> 46256

Sheet D57 San Pablo
H1: San Pablo | X1: =AVERAGE(L7,L9,L13,L17) -> 1.054544 | Y1: =1-X1 -> -0.054544026
H4: Tipo | I4: Distrito | J4: Meta | K4: Contabilidad | L4: % Avance | M4: Pendiente
H5: Comunidad
I7: San Pablo | J7: 252 | K7: 253 | L7: =K7/J7 -> 1.0039683 | M7: =J7-K7 -> -1
I9: Rincon de Sabanilla | J9: 128 | K9: 145 | L9: =K9/J9 -> 1.1328125 | M9: =J9-K9 -> -17
H11: Comercio
I13: San Pablo | J13: 86 | K13: 93 | L13: =K13/J13 -> 1.0813953 | M13: =J13-K13 -> -7
H15: Policial
I17: San Pablo | J17: 22 | K17: 22 | L17: =K17/J17 -> 1 | M17: =J17-K17 -> 0
I20: =TODAY() -> 46256

Sheet R5
A1: Delegacion Policial | X1: =AVERAGE(C3:C13) -> 1.1454095 | Y1: =1-X1 -> -0.14540947
A3: D60-Liberia | C3: ='D60 Liberia'!X1 -> 1.3675844
A4: D61-Nicoya | C4: ='D61 Nicoya'!X1 -> 1.1080596
A5: D62-Santa Cruz | C5: ='D62 Santa Cruz'!X1 -> 1.5554786
A6: D63-Bagaces | C6: ='D63 Bagaces'!X1 -> 0.87167116
A7: D64-Carrillo | C7: ='D64 Carrillo'!X1 -> 1.0631827
A8: D65-Cañas | C8: ='D65 Cañas'!X1 -> 1.1491593
A9: D66-Abangares | C9: ='D66 Abangares'!X1 -> 1.0217808
A10: D67-Tilarán | C10: ='D67 Tilaran'!X1 -> 1.0569699
A11: D68-Nandayure | C11: ='D68 Nandayure'!X1 -> 1.1068533
A12: D69-Hojancha | C12: ='D69 Hojancha'!X1 -> 1.1314247
A13: D70-La Cruz | C13: ='D70 La Cruz'!X1 -> 1.1673398

Sheet D60 Liberia
H1: Liberia | X1: =AVERAGE(L7,L9,L11,L13,L15,L19,L23) -> 1.3675844 | Y1: =1-X1 -> -0.3675844
H4: Tipo | I4: Distrito | J4: Meta | K4: Contabilidad | L4: % Avance | M4: Pendiente
H5: Comunidad
I7: Liberia | J7: 322 | K7: 383 | L7: =K7/J7 -> 1.189441 | M7: =J7-K7 -> -61
I9: Cañas Dulces | J9: 20 | K9: 24 | L9: =K9/J9 -> 1.2 | M9: =J9-K9 -> -4
I11: Mayorga | J11: 10 | K11: 23 | L11: =K11/J11 -> 2.3 | M11: =J11-K11 -> -13
I13: Nacascolo | J13: 15 | K13: 26 | L13: =K13/J13 -> 1.7333333 | M13: =J13-K13 -> -11
I15: Curubande | J15: 16 | K15: 18 | L15: =K15/J15 -> 1.125 | M15: =J15-K15 -> -2
H17: Comercio
I19: Liberia | J19: 191 | K19: 191 | L19: =K19/J19 -> 1 | M19: =J19-K19 -> 0
H21: Policial
I23: Liberia | J23: 79 | K23: 81 | L23: =K23/J23 -> 1.0253165 | M23: =J23-K23 -> -2
I26: =TODAY() -> 46256

Sheet D61 Nicoya
H1: Nicoya | X1: =AVERAGE(L7,L9,L11,L13,L15,L17,L19,L23,L27) -> 1.1080596 | Y1: =1-X1 -> -0.10805965
H4: Tipo | I4: Distrito | J4: Meta | K4: Contabilidad | L4: % Avance | M4: Pendiente
H5: Comunidad
I7: Nicoya | J7: 177 | K7: 179 | L7: =K7/J7 -> 1.0112994 | M7: =J7-K7 -> -2
I9: Mansion | J9: 35 | K9: 35 | L9: =K9/J9 -> 1 | M9: =J9-K9 -> 0
I11: San Antonio | J11: 46 | K11: 46 | L11: =K11/J11 -> 1 | M11: =J11-K11 -> 0
I13: Quebrada Honda | J13: 16 | K13: 23 | L13: =K13/J13 -> 1.4375 | M13: =J13-K13 -> -7
I15: Samara | J15: 33 | K15: 35 | L15: =K15/J15 -> 1.0606061 | M15: =J15-K15 -> -2
I17: Nosara | J17: 54 | K17: 57 | L17: =K17/J17 -> 1.0555556 | M17: =J17-K17 -> -3
I19: Belen de Nosarita | J19: 20 | K19: 24 | L19: =K19/J19 -> 1.2 | M19: =J19-K19 -> -4
H21: Comercio
I23: Nicoya | J23: 132 | K23: 133 | L23: =K23/J23 -> 1.0075758 | M23: =J23-K23 -> -1
H25: Policial
I27: Nicoya | J27: 125 | K27: 150 | L27: =K27/J27 -> 1.2 | M27: =J27-K27 -> -25
I30: =TODAY() -> 46256

Sheet D62 Santa Cruz
H1: Santa Cruz | X1: =AVERAGE(L7,L9,L11,L13,L15,L17,L19,L21,L23,L27,L31) -> 1.5554786 | Y1: =1-X1 -> -0.55547856
H4: Tipo | I4: Distrito | J4: Meta | K4: Contabilidad | L4: % Avance | M4: Pendiente
H5: Comunidad
I7: Santa Cruz | J7: 145 | K7: 171 | L7: =K7/J7 -> 1.1793103 | M7: =J7-K7 -> -26
I9: Bolson | J9: 12 | K9: 27 | L9: =K9/J9 -> 2.25 | M9: =J9-K9 -> -15
I11: Veintisiete de Abril | J11: 51 | K11: 51 | L11: =K11/J11 -> 1 | M11: =J11-K11 -> 0
I13: Tempate | J13: 36 | K13: 54 | L13: =K13/J13 -> 1.5 | M13: =J13-K13 -> -18
I15: Cartagena | J15: 28 | K15: 32 | L15: =K15/J15 -> 1.1428571 | M15: =J15-K15 -> -4
I17: Cuajiniquil | J17: 15 | K17: 20 | L17: =K17/J17 -> 1.3333333 | M17: =J17-K17 -> -5
I19: Diria | J19: 26 | K19: 33 | L19: =K19/J19 -> 1.2692308 | M19: =J19-K19 -> -7
I21: Cabo Velas | J21: 25 | K21: 55 | L21: =K21/J21 -> 2.2 | M21: =J21-K21 -> -30
I23: Tamarindo | J23: 45 | K23: 139 | L23: =K23/J23 -> 3.0888889 | M23: =J23-K23 -> -94
H25: Comercio
I27: Santa Cruz | J27: 166 | K27: 169 | L27: =K27/J27 -> 1.0180723 | M27: =J27-K27 -> -3
H29: Policial
I31: Santa Cruz | J31: 70 | K31: 79 | L31: =K31/J31 -> 1.1285714 | M31: =J31-K31 -> -9
I34: =TODAY() -> 46256

Sheet D63 Bagaces
H1: Bagaces | X1: =AVERAGE(L7,L9,L11,L13,L17,L21) -> 0.87167116 | Y1: =1-X1 -> 0.12832884
H4: Tipo | I4: Distrito | J4: Meta | K4: Contabilidad | L4: % Avance | M4: Pendiente
H5: Comunidad
I7: Bagaces | J7: 259 | K7: 187 | L7: =K7/J7 -> 0.72200772 | M7: =J7-K7 -> 72
I9: Fortuna | J9: 44 | K9: 44 | L9: =K9/J9 -> 1 | M9: =J9-K9 -> 0
I11: Mogote | J11: 58 | K11: 47 | L11: =K11/J11 -> 0.81034483 | M11: =J11-K11 -> 11
I13: Rio Naranjo | J13: 18 | K13: 18 | L13: =K13/J13 -> 1 | M13: =J13-K13 -> 0
H15: Comercio
I17: Bagaces | J17: 43 | K17: 30 | L17: =K17/J17 -> 0.69767442 | M17: =J17-K17 -> 13
H19: Policial
I21: Bagaces | J21: 38 | K21: 38 | L21: =K21/J21 -> 1 | M21: =J21-K21 -> 0
I24: =TODAY() -> 46256

Sheet D64 Carrillo
H1: Carrillo | X1: =AVERAGE(L7,L9,L11,L13,L17,L21) -> 1.0631827 | Y1: =1-X1 -> -0.063182712
H4: Tipo | I4: Distrito | J4: Meta | K4: Contabilidad | L4: % Avance | M4: Pendiente
H5: Comunidad
I7: Filadelfia | J7: 65 | K7: 84 | L7: =K7/J7 -> 1.2923077 | M7: =J7-K7 -> -19
I9: Palmira | J9: 56 | K9: 41 | L9: =K9/J9 -> 0.73214286 | M9: =J9-K9 -> 15
I11: Sardinal | J11: 165 | K11: 167 | L11: =K11/J11 -> 1.0121212 | M11: =J11-K11 -> -2
I13: Belen | J13: 96 | K13: 127 | L13: =K13/J13 -> 1.3229167 | M13: =J13-K13 -> -31
H15: Comercio
I17: Carrillo | J17: 102 | K17: 104 | L17: =K17/J17 -> 1.0196078 | M17: =J17-K17 -> -2
H19: Policial
I21: Carrillo | J21: 42 | K21: 42 | L21: =K21/J21 -> 1 | M21: =J21-K21 -> 0
I24: =TODAY() -> 46256

Sheet D65 Cañas
H1: Cañas | X1: =AVERAGE(L7,L9,L11,L13,L15,L19,L23) -> 1.1491593 | Y1: =1-X1 -> -0.14915927
H4: Tipo | I4: Distrito | J4: Meta | K4: Contabilidad | L4: % Avance | M4: Pendiente
H5: Comunidad
I7: Cañas | J7: 303 | K7: 311 | L7: =K7/J7 -> 1.0264026 | M7: =J7-K7 -> -8
I9: Palmira | J9: 16 | K9: 17 | L9: =K9/J9 -> 1.0625 | M9: =J9-K9 -> -1
I11: San Miguel | J11: 23 | K11: 25 | L11: =K11/J11 -> 1.0869565 | M11: =J11-K11 -> -2
I13: Bebedero | J13: 29 | K13: 42 | L13: =K13/J13 -> 1.4482759 | M13: =J13-K13 -> -13
I15: Porozal | J15: 9 | K15: 12 | L15: =K15/J15 -> 1.3333333 | M15: =J15-K15 -> -3
H17: Comercio
I19: Cañas | J19: 89 | K19: 95 | L19: =K19/J19 -> 1.0674157 | M19: =J19-K19 -> -6
H21: Policial
I23: Cañas | J23: 52 | K23: 53 | L23: =K23/J23 -> 1.0192308 | M23: =J23-K23 -> -1
I26: =TODAY() -> 46256

Sheet D66 Abangares
H1: Abangares | X1: =AVERAGE(L7,L9,L11,L13,L17,L21) -> 1.0217808 | Y1: =1-X1 -> -0.021780819
H4: Tipo | I4: Distrito | J4: Meta | K4: Contabilidad | L4: % Avance | M4: Pendiente
H5: Comunidad
I7: Juntas | J7: 192 | K7: 189 | L7: =K7/J7 -> 0.984375 | M7: =J7-K7 -> 3
I9: Sierra | J9: 54 | K9: 56 | L9: =K9/J9 -> 1.037037 | M9: =J9-K9 -> -2
I11: San Juan | J11: 36 | K11: 37 | L11: =K11/J11 -> 1.0277778 | M11: =J11-K11 -> -1
I13: Colorado | J13: 96 | K13: 101 | L13: =K13/J13 -> 1.0520833 | M13: =J13-K13 -> -5
H15: Comercio
I17: Abangares | J17: 51 | K17: 51 | L17: =K17/J17 -> 1 | M17: =J17-K17 -> 0
H19: Policial
I21: Abangares | J21: 34 | K21: 35 | L21: =K21/J21 -> 1.0294118 | M21: =J21-K21 -> -1
I24: =TODAY() -> 46256

Sheet D67 Tilaran
H1: Tilaran | X1: =AVERAGE(L7,L9,L11,L13,L15,L17,L19,L21,L25,L29) -> 1.0569699 | Y1: =1-X1 -> -0.056969919
H4: Tipo | I4: Distrito | J4: Meta | K4: Contabilidad | L4: % Avance | M4: Pendiente
H5: Comunidad
I7: Tilaran | J7: 141 | K7: 143 | L7: =K7/J7 -> 1.0141844 | M7: =J7-K7 -> -2
I9: Quebrada Grande | J9: 47 | K9: 49 | L9: =K9/J9 -> 1.0425532 | M9: =J9-K9 -> -2
I11: Tronadora | J11: 31 | K11: 32 | L11: =K11/J11 -> 1.0322581 | M11: =J11-K11 -> -1
I13: Santa Rosa | J13: 34 | K13: 37 | L13: =K13/J13 -> 1.0882353 | M13: =J13-K13 -> -3
I15: Libano | J15: 15 | K15: 17 | L15: =K15/J15 -> 1.1333333 | M15: =J15-K15 -> -2
I17: Tierra Morenas | J17: 24 | K17: 24 | L17: =K17/J17 -> 1 | M17: =J17-K17 -> 0
I19: Arenal | J19: 41 | K19: 41 | L19: =K19/J19 -> 1 | M19: =J19-K19 -> 0
I21: Cabeceras | J21: 46 | K21: 52 | L21: =K21/J21 -> 1.1304348 | M21: =J21-K21 -> -6
H23: Comercio
I25: Tilaran | J25: 74 | K25: 80 | L25: =K25/J25 -> 1.0810811 | M25: =J25-K25 -> -6
H27: Policial
I29: Tilaran | J29: 42 | K29: 44 | L29: =K29/J29 -> 1.047619 | M29: =J29-K29 -> -2
I32: =TODAY() -> 46256

Sheet D68 Nandayure
H1: Nandayure | X1: =AVERAGE(L7,L9,L11,L13,L15,L17,L21,L25) -> 1.1068533 | Y1: =1-X1 -> -0.10685326
H4: Tipo | I4: Distrito | J4: Meta | K4: Contabilidad | L4: % Avance | M4: Pendiente
H5: Comunidad
I7: Carmona | J7: 89 | K7: 110 | L7: =K7/J7 -> 1.2359551 | M7: =J7-K7 -> -21
I9: Santa Rita | J9: 46 | K9: 49 | L9: =K9/J9 -> 1.0652174 | M9: =J9-K9 -> -3
I11: Zapotal | J11: 39 | K11: 46 | L11: =K11/J11 -> 1.1794872 | M11: =J11-K11 -> -7
I13: San Pablo | J13: 73 | K13: 73 | L13: =K13/J13 -> 1 | M13: =J13-K13 -> 0
I15: Porvenir | J15: 24 | K15: 29 | L15: =K15/J15 -> 1.2083333 | M15: =J15-K15 -> -5
I17: Bejuco | J17: 102 | K17: 111 | L17: =K17/J17 -> 1.0882353 | M17: =J17-K17 -> -9
H19: Comercio
